Workbook
Name __HWP14: '[1]0-ハード（その他)'!#REF!
Name __HWP14: '[1]0-ハード（その他)'!#REF!
Name __HWP14: '[1]0-ハード（その他)'!#REF!
Name __HWP14: '[1]0-ハード（その他)'!#REF!
Name _HWP13: '[1]0-ハード（その他)'!#REF!
Name ABC: #REF!
Name ABC: #REF!
Name ABC: #REF!
Name ABC: #REF!
Name ABCDEFF: '[1]0-ハード（その他)'!#REF!
Name ABCDEFG: '[1]0-ハード（その他)'!#REF!
Name ABCDEFG: '[1]0-ハード（その他)'!#REF!
Name ABCDEFG: '[1]0-ハード（その他)'!#REF!
Name ABCDEFG: '[1]0-ハード（その他)'!#REF!
Name ACC: #REF!
Name dasd: #REF!
Name dasd: #REF!
Name dasd: #REF!
Name dasd: #REF!
Name DD: #REF!
Name DD: #REF!
Name DD: #REF!
Name DD: #REF!
Name DELIVALY_AUO_REQ: #REF!
Name DELIVALY_AUO_REQ: #REF!
Name DELIVALY_AUO_REQ: #REF!
Name DELIVALY_AUO_REQ: #REF!
Name DURATION: #REF!
Name DURATION: #REF!
Name DURATION: #REF!
Name DURATION: #REF!
Name EQ_Table: #REF!
Name EQ_Table: #REF!
Name EQ_Table: #REF!
Name EQ_Table: #REF!
Name EQPORT304: #REF!
Name EQPORT304: #REF!
Name EQPORT304: #REF!
Name EQPORT304: #REF!
Name EQPORT305: #REF!
Name EQPORT305: #REF!
Name EQPORT305: #REF!
Name EQPORT305: #REF!
Name EQPORT306: #REF!
Name EQPORT306: #REF!
Name EQPORT306: #REF!
Name EQPORT306: #REF!
Name EQPORT307: #REF!
Name EQPORT307: #REF!
Name EQPORT307: #REF!
Name EQPORT307: #REF!
Name HWPP14: '[1]0-ハード（その他)'!#REF!
Name HWPP14: '[1]0-ハード（その他)'!#REF!
Name HWPP14: '[1]0-ハード（その他)'!#REF!
Name HWPP14: '[1]0-ハード（その他)'!#REF!
Name MOVEMENT: #REF!
Name MOVEMENT: #REF!
Name MOVEMENT: #REF!
Name MOVEMENT: #REF!
Name REWORK: #REF!

Sheet 개요
B2: V3 (Semi C/V, STOCKER) ↔ Web 관제 프로토콜 정의서
B4: 문서 버전 | C4: v1.1
B5: 작성일 | C5: 2026-07-11
B6: 초안자 | C6: 장병찬K
B7: 대상 프로그램 | C7: V3 (Semi C/V · STOCKER 설비 제어 프로그램)
B8: 통신 방식 | C8: WebSocket · JSON
B9: 엔드포인트 | C9: ws://<V3 PC IP>:8765/ws/dashboard
B10: 공통 Envelope (수신) | C10: { "type": string, "siteId": string, "timestamp": ISO8601, "data": ... }
B11: 송신 형식 | C11: { "type": "COMMAND", "data": { "cmd": string, ... } }
B12: 하트비트 | C12: HEARTBEAT 15초 무수신 시 Web이 강제 재연결 (재연결 백오프 1s→최대 30s)
B13: 소스 기준 | C13: src/constants/protocolCatalog.ts · src/types/semicnv.ts (코드가 원본, 이 문서는 사본)
B14: 설비 모드 선택 | C14: V3 시작 시 Semi C/V 또는 STOCKER 모드를 선택 → 해당 모드의 메모리맵을 참조해 동일 Envelope로 Web에 전송. 구분자: data.equipmentType ('SEMI_CNV' | 'STOCKER'), 미지정 시 'SEMI_CNV'로 간주.
B15: STOCKER 소스 기준 | C15: SS-One BIT/Word Communication · Port Bit/Word (구 STOCKER–CIM TCP/IP Memory Map) 을 WebSocket JSON 으로 재정의

Sheet 메시지 목록
A1: No. | B1: 방향 | C1: 모드 | D1: TYPE | E1: 이름 | F1: 설명 | G1: 필드 수
A2: 1 | B2: 수신 | C2: Semi C/V | D2: SITE_CONNECT | E2: 현장 접속 통지 | F2: V3가 연결 직후 1회 전송 — 현장 이름·프로그램 버전·설비 규모를 알린다. | G2: =COUNTIFS('필드 정의'!$A:$A,D2,'필드 정의'!$B:$B,C2) -> 5
A3: 2 | B3: 수신 | C3: Semi C/V | D3: CONVEYOR_STATUS | E3: 컨베이어 상태 | F3: 유닛별 실시간 상태 배열 — 가동/알람/자재(cstId)/회전각 등. 주기 전송. | G3: =COUNTIFS('필드 정의'!$A:$A,D3,'필드 정의'!$B:$B,C3) -> 17
A4: 3 | B4: 수신 | C4: Semi C/V | D4: LINE_STATUS | E4: 라인 상태 | F4: 라인 단위 요약 배열 — Safety/Key/Auto Condition·가동/알람 컨베이어 수. | G4: =COUNTIFS('필드 정의'!$A:$A,D4,'필드 정의'!$B:$B,C4) -> 10
A5: 4 | B5: 수신 | C5: Semi C/V | D5: ALARM_EVENT | E5: 알람 이벤트 | F5: 알람 발생(OCCUR)/해제(CLEAR) 즉시 통지 — 알람 리스트·이력에 반영. | G5: =COUNTIFS('필드 정의'!$A:$A,D5,'필드 정의'!$B:$B,C5) -> 7
A6: 5 | B6: 수신 | C6: Semi C/V | D6: CST_TRACKING | E6: CST 위치 추적 | F6: 자재(CST)가 어느 유닛에 있는지 배열로 통지 — 타임차트 V3 핸드셰이크 기록의 근거. | G6: =COUNTIFS('필드 정의'!$A:$A,D6,'필드 정의'!$B:$B,C6) -> 4
A7: 6 | B7: 수신 | C7: Semi C/V | D7: IO_STATUS | E7: IO 상태 상세 | F7: Safety/Auto Condition 항목별 ON/OFF + 프로그램 상태 — 설비 상태 탭·조건 팝업에 표시. | G7: =COUNTIFS('필드 정의'!$A:$A,D7,'필드 정의'!$B:$B,C7) -> 6
A8: 7 | B8: 수신 | C8: 공용 | D8: LOG_EVENT | E8: 로그 스트리밍 | F8: V3 로그 실시간 전송 — "V3 이력" 탭·이력 화면에 축적. | G8: =COUNTIFS('필드 정의'!$A:$A,D8,'필드 정의'!$B:$B,C8) -> 5
A9: 8 | B9: 수신 | C9: 공용 | D9: HEARTBEAT | E9: 하트비트 | F9: 생존 신호 — 15초 무수신 시 Web이 강제 재연결. | G9: =COUNTIFS('필드 정의'!$A:$A,D9,'필드 정의'!$B:$B,C9) -> 1
A10: 9 | B10: 송신 | C10: Semi C/V | D10: COMMAND | E10: 제어 명령 | F10: Web → V3 제어 명령. 정의된 cmd: all_power_on · all_power_off · all_auto_run · all_auto_stop · alarm_reset (전체 대상). 개별 유닛 명령은 미정의 — 스펙 확정 시 확장 예정. | G10: =COUNTIFS('필드 정의'!$A:$A,D10,'필드 정의'!$B:$B,C10) -> 2
A11: 10 | B11: 수신 | C11: STOCKER | D11: SITE_CONNECT | E11: 현장 접속 통지 (스토커) | F11: V3가 STOCKER 모드로 연결 직후 1회 전송 — equipmentType=STOCKER, 스토커·랙마스터·포트·셀프 규모를 알린다. | G11: =COUNTIFS('필드 정의'!$A:$A,D11,'필드 정의'!$B:$B,C11) -> 7
A12: 11 | B12: 수신 | C12: STOCKER | D12: LINE_STATUS | E12: 스토커 본체 상태 | F12: 스토커 본체 단위 요약 — 제어/운전 모드·온라인·안전·타워램프·도어·EMO·팬·CST Full·적재수·포트 요약·CPS 전원. 주기 전송. | G12: =COUNTIFS('필드 정의'!$A:$A,D12,'필드 정의'!$B:$B,C12) -> 19
A13: 12 | B13: 수신 | C13: STOCKER | D13: CONVEYOR_STATUS | E13: 유닛 상태 (크레인·포트) | F13: 유닛별 실시간 상태 배열 — unitType으로 Rack Master(크레인)/Port 구분. 크레인 서보·모드·반송동작·스텝, 포트 PIO 핸드셰이크·캐리어ID 등. | G13: =COUNTIFS('필드 정의'!$A:$A,D13,'필드 정의'!$B:$B,C13) -> 24
... A17: 16 | B17: 송신 | C17: STOCKER | D17: COMMAND | E17: 제어 명령 (스토커) | F17: Web → V3 스토커 제어. 본체(비상정지·에러리셋·형광등·타워램프)·크레인(서보·자동·원점·반송·티칭·시간동기)·포트(run/stop/power/in-out mode/reset) 명령을 target으로 지정. | G17: =COUNTIFS('필드 정의'!$A:$A,D17,'필드 정의'!$B:$B,C17) -> 4

Sheet 필드 정의
A1: 메시지 TYPE | B1: 모드 | C1: 방향 | D1: 필드 | E1: 타입 | F1: 필수 | G1: 설명
A2: SITE_CONNECT | B2: Semi C/V | C2: 수신 | D2: siteName | E2: string | F2: 필수 | G2: 현장(Site) 이름
A3: SITE_CONNECT | B3: Semi C/V | C3: 수신 | D3: programVersion | E3: string | F3: 필수 | G3: V3 프로그램 버전
A4: SITE_CONNECT | B4: Semi C/V | C4: 수신 | D4: apiKey | E4: string | F4: 옵션 | G4: 인증 키 (옵션)
A5: SITE_CONNECT | B5: Semi C/V | C5: 수신 | D5: lineCount | E5: number | F5: 필수 | G5: 라인 수
A6: SITE_CONNECT | B6: Semi C/V | C6: 수신 | D6: conveyorCount | E6: number | F6: 필수 | G6: 컨베이어 수
A7: CONVEYOR_STATUS | B7: Semi C/V | C7: 수신 | D7: id | E7: number | F7: 필수 | G7: Conveyor.ID (semiCnvId 매핑)
A8: CONVEYOR_STATUS | B8: Semi C/V | C8: 수신 | D8: lineId | E8: number | F8: 필수 | G8: 소속 라인 ID
A9: CONVEYOR_STATUS | B9: Semi C/V | C9: 수신 | D9: name | E9: string | F9: 필수 | G9: 유닛 이름 (CV01 등)
A10: CONVEYOR_STATUS | B10: Semi C/V | C10: 수신 | D10: conveyorType | E10: 'None'|'Normal'|'Turn'|'LFT'|'ZT'|'RX'|'Up_Down' | F10: 필수 | G10: 유닛 타입
A11: CONVEYOR_STATUS | B11: Semi C/V | C11: 수신 | D11: controlMode | E11: 'MasterMode'|'CIMMode' | F11: 필수 | G11: 제어 모드
A12: CONVEYOR_STATUS | B12: Semi C/V | C12: 수신 | D12: runStatus | E12: 'Run'|'Stop' | F12: 필수 | G12: 구동 여부
... A139: COMMAND | B139: STOCKER | C139: 송신 | D139: params | E139: Record<string, unknown> | F139: 옵션 | G139: 명령별 추가 파라미터 (rm_transfer: fromShelfId/toShelfId, rm_teaching_start: shelfId, tower_lamp_set: color/mode 등)

Sheet 예시 JSON
B1: Semi C/V 모드 예시 (equipmentType = "Conveyor") | E1: STOCKER 모드 예시 (equipmentType = "STOCKER")
B3: SITE_CONNECT (수신) | E3: SITE_CONNECT (수신, STOCKER)
C4: { "type": "SITE_CONNECT", "siteId": "site-A", "timestamp": "2026-07-11T09:00:00.000Z", "data": { "siteName": "음성공장", "programVersion": "3.1.0", "lineCount": 2, "conveyorCount": 24 } } | F4: { "type": "SITE_CONNECT", "siteId": "site-B", "timestamp": "2026-07-11T09:00:00.000Z", "data": { "equipmentType": "STOCKER", "siteName": "음성공장 STK-A", "programVersion": "3.1.0", "stockerCount": 1, "rackMasterCount": 1, "portCount": 4, "shelfCount": 240 } }
B6: CONVEYOR_STATUS (수신) | E6: LINE_STATUS (수신, STOCKER) — 스토커 본체 요약
C7: { "type": "CONVEYOR_STATUS", "siteId": "site-A", "timestamp": "2026-07-11T09:00:01.000Z", "data": [ { "id": 1, "lineId": 0, "name": "CV01", "conveyorType": "Normal", "controlMode": "MasterMode", "runStatus": "Run", "operationStatus": "Auto", "autoStatus": "Busy", "autoStep": 3, "power": "On", "alarm": false, "cstId": "CST-0077", "destination": 5 } ] } | F7: { "type": "LINE_STATUS", "siteId": "site-B", "timestamp": "2026-07-11T09:00:01.000Z", "data": [ { "equipmentType": "STOCKER", "stockerId": 1, "stockerName": "STK-01", "controlMode": "CIMMode", "operationStatus": "Auto", "onlineStatus": "Online", "safetyStatus": "OK", "alarmStatus": false, "towerLamp": { "green": true, "yellow": false, "red": false, "buzzer": false }, "doorOpen": false, "emoPushed": false, "keyAuto": true, "fanStatus": { "intake": true, "exhaust": true }, "cstFull": false, "storedCstCount": 128, "totalPorts": 4, "runningPorts": 3, "alarmCount": 0, "cps": [ { "no": 1, "run": true, "error": false, "failover": false }, { "no": 2, "run": true, "error": false, "failover": false } ] } ] }
B9: LINE_STATUS (수신) | E9: CONVEYOR_STATUS (수신, STOCKER) — 크레인·포트 유닛
C10: { "type": "LINE_STATUS", "siteId": "site-A", "timestamp": "2026-07-11T09:00:01.000Z", "data": [ { "lineId": 0, "lineName": "LINE-1", "safetyStatus": "OK", "keyStatus": "Auto", "autoCondition": "Possible", "operationStatus": "Auto", "controlMode": "MasterMode", "totalConveyors": 12, "runningConveyors": 9, "alarmConveyors": 0 } ] } | F10: { "type": "CONVEYOR_STATUS", "siteId": "site-B", "timestamp": "2026-07-11T09:00:01.000Z", "data": [ { "equipmentType": "STOCKER", "id": 1, "stockerId": 1, "unitType": "RackMaster", "name": "RM01", "alarm": false, "servoOn": true, "controlMode": "CIMMode", "operationStatus": "Auto", "activity": "Active", "transferType": "To", "autoStep": 12, "homeDone": true, "fromShelfId": 15, "toShelfId": 132, "accessShelfId": 132, "cstId": "CST-0077", "cstPresent": true }, { "equipmentType": "STOCKER", "id": 101, "stockerId": 1, "unitType": "Port", "name": "MGV-IN", "alarm": false, "portType": "MGV", "direction": "In", "pioStatus": "Transferring", "carrierId": "CST-0091", "runEnable": true, "lightCurtain": false } ] }
B12: ALARM_EVENT (수신) | E12: ALARM_EVENT (수신, STOCKER)
C13: { "type": "ALARM_EVENT", "siteId": "site-A", "timestamp": "2026-07-11T09:00:02.000Z", "data": { "eventType": "OCCUR", "conveyorId": 3, "lineId": 0, "alarmCode": "3001", "alarmLevel": "Error", "alarmStep": 4, "message": "CV03 MOTOR OVERLOAD" } } | F13: { "type": "ALARM_EVENT", "siteId": "site-B", "timestamp": "2026-07-11T09:00:02.000Z", "data": { "equipmentType": "STOCKER", "eventType": "OCCUR", "source": "RackMaster", "unitId": 1, "stockerId": 1, "alarmCode": "RM-2043", "alarmLevel": "Error", "alarmStep": 12, "message": "RM01 Z-AXIS SERVO ERROR", "axis": "Z" } }
B15: CST_TRACKING (수신) | E15: CST_TRACKING (수신, STOCKER)
C16: { "type": "CST_TRACKING", "siteId": "site-A", "timestamp": "2026-07-11T09:00:03.000Z", "data": [ { "cstId": "CST-0077", "conveyorId": 2, "lineId": 0, "destination": 5 } ] } | F16: { "type": "CST_TRACKING", "siteId": "site-B", "timestamp": "2026-07-11T09:00:03.000Z", "data": [ { "equipmentType": "STOCKER", "cstId": "CST-0077", "locationType": "Fork", "shelfId": null, "portId": null, "stockerId": 1, "fromShelfId": 15, "toShelfId": 132 } ] }
B18: IO_STATUS (수신) | E18: IO_STATUS (수신, STOCKER) — 조건·축 텔레메트리
C19: { "type": "IO_STATUS", "siteId": "site-A", "timestamp": "2026-07-11T09:00:04.000Z", "data": { "safetyOk": true, "safetyConditions": [ { "no": 1, "name": "EMO", "status": true } ], "autoConditionOk": false, "autoConditions": [ { "no": 1, "name": "Home Done", "status": false } ], "currentStatus": "Standby", "programStatus": [ { "item": "Version", "value": "3.1.0" } ] } } | F19: { "type": "IO_STATUS", "siteId": "site-B", "timestamp": "2026-07-11T09:00:04.000Z", "data": { "equipmentType": "STOCKER", "stockerId": 1, "safetyOk": true, "safetyConditions": [ { "no": 1, "name": "EMO", "status": true }, { "no": 2, "name": "Front Door", "status": true } ], "autoConditionOk": true, "autoConditions": [ { "no": 1, "name": "Servo On", "status": true }, { "no": 2, "name": "Home Done", "status": true } ], "axes": [ { "axis": "X", "currentPos": 12450.5, "targetPos": 12450.5, "currentSpeed": 0.0, "torque": 8.2, "avgTorque": 7.5, "peakTorque": 22.1, "travelDistance": 184203.4, "homeDone": true, "servoOn": true }, { "axis": "Z", "currentPos": 3200.0, "targetPos": 3200.0, "currentSpeed": 0.0, "torque": 5.1, "avgTorque": 4.8, "peakTorque": 18.7, "travelDistance": 95820.1, "homeDone": true, "servoOn": true } ], "sensors": [ { "name": "Fork CST Present", "status": true }, { "name": "Fork Protrusion", "status": false } ], "programStatus": [ { "item": "Version", "value": "3.1.0" } ] } }
B21: LOG_EVENT (수신) | E21: COMMAND (송신, STOCKER) — 반송 지시 예시
C22: { "type": "LOG_EVENT", "siteId": "site-A", "timestamp": "2026-07-11T09:00:05.000Z", "data": { "logTime": "2026-07-11T09:00:05.000", "logType": "Application", "logLevel": "Normal", "title": "Auto Run", "description": "All conveyor auto run started" } } | F22: { "type": "COMMAND", "data": { "equipmentType": "STOCKER", "cmd": "rm_transfer", "target": { "kind": "RackMaster", "id": 1 }, "params": { "fromShelfId": 15, "toShelfId": 132 } } }
B24: HEARTBEAT (수신)
C25: { "type": "HEARTBEAT", "siteId": "site-A", "timestamp": "2026-07-11T09:00:06.000Z", "data": { "status": "ALIVE" } }
B27: COMMAND (송신)
C28: { "type": "COMMAND", "data": { "cmd": "all_auto_run" } }

Sheet SS-One BIT Communication
B1: SS-One <--> MST Communication BIT Map
A2: Master Program Comment | B2: [SS-One] --> [Master] | I2: Comment | J2: 비고 | K2: Bit | L2: [Master] --> [SS-One] | S2: Comment | T2: 비고 | U2: Master Program Comment
B3: Dec | D3: Hex | K3: Per Word | L3: Dec | N3: Hex
A4: WMX Output 연동 | B4: 0 | D4: =CONCATENATE("0x", DEC2HEX(B4,2)) -> 0x00 | I4: Door Open | J4: 1이면 오픈 0이면 닫음 | K4: 1 | L4: 0 | N4: =CONCATENATE("0x", DEC2HEX(L4,2)) -> 0x00 | S4: HP Door 열림 상태 | T4: 1 열림, 0 닫힘 | U4: WMX Input 연동
B5: 1 | D5: =CONCATENATE("0x", DEC2HEX(B5,2)) -> 0x01 | L5: 1 | N5: =CONCATENATE("0x", DEC2HEX(L5,2)) -> 0x01 | S5: HP EMO 눌림 상태 | T5: 1 눌림, 0 정상 | U5: WMX Input 연동
A6: Not Update | B6: 2 | D6: =CONCATENATE("0x", DEC2HEX(B6,2)) -> 0x02 | I6: SSO->MST Online/Offline 상 태******** | L6: 2 | N6: =CONCATENATE("0x", DEC2HEX(L6,2)) -> 0x02 | S6: HP MASTER KEY 자동 Mode 상태 | T6: 1이 정상, 0이 비정상 | U6: WMX Input 연동
A7: Not Update | B7: 3 | D7: =CONCATENATE("0x", DEC2HEX(B7,2)) -> 0x03 | I7: SSO->MSTCST Full상 태******** | L7: 3 | N7: =CONCATENATE("0x", DEC2HEX(L7,2)) -> 0x03
B8: 4 | D8: =CONCATENATE("0x", DEC2HEX(B8,2)) -> 0x04 | L8: 4 | N8: =CONCATENATE("0x", DEC2HEX(L8,2)) -> 0x04
A9: WMX Output 연동 | B9: 5 | D9: =CONCATENATE("0x", DEC2HEX(B9,2)) -> 0x05 | I9: SSO->MST 타워램프 Green | L9: 5 | N9: =CONCATENATE("0x", DEC2HEX(L9,2)) -> 0x05 | S9: HP 비상탈출 눌림상태 | T9: 1 눌림, 0 정상 | U9: WMX Input 연동
A10: WMX Output 연동 | B10: 6 | D10: =CONCATENATE("0x", DEC2HEX(B10,2)) -> 0x06 | I10: SSO->MST 타워램프 YELLOW | L10: 6 | N10: =CONCATENATE("0x", DEC2HEX(L10,2)) -> 0x06
A11: WMX Output 연동 | B11: 7 | D11: =CONCATENATE("0x", DEC2HEX(B11,2)) -> 0x07 | I11: SSO->MST 타워램프 RED | L11: 7 | N11: =CONCATENATE("0x", DEC2HEX(L11,2)) -> 0x07 | S11: OP Door 열림 상태 | T11: 1 열림, 0 닫힘 | U11: WMX Input 연동
A12: WMX Output 연동 | B12: 8 | D12: =CONCATENATE("0x", DEC2HEX(B12,2)) -> 0x08 | I12: SSO->MST 타워램프 BUZZER 경알람 | J12: 마스터 알람 발생 시 | L12: 8 | N12: =CONCATENATE("0x", DEC2HEX(L12,2)) -> 0x08 | S12: OP EMO 눌림 상태 | T12: 1 눌림, 0 정상 | U12: WMX Input 연동
A13: WMX Output 연동 | B13: 9 | D13: =CONCATENATE("0x", DEC2HEX(B13,2)) -> 0x09 | I13: SSO->MST 타워램프 BUZZER 중알람 | J13: 포트 알람 발생 시 | L13: 9 | N13: =CONCATENATE("0x", DEC2HEX(L13,2)) -> 0x09 | S13: RM HP Handy Touch EMO 눌림상태 | T13: 1 눌림, 0 정상
A14: WMX Output 연동 | B14: 10 | D14: =CONCATENATE("0x", DEC2HEX(B14,2)) -> 0x0A | H14: 2023.07.28 | I14: SSO->MST 타워램프 BUZZER Active | J14: 랙마스터 액티브 상태 | L14: 10 | N14: =CONCATENATE("0x", DEC2HEX(L14,2)) -> 0x0A | S14: RM OP Handy Touch EMO 눌림상태 | T14: 1 눌림, 0 정상
B15: 11 | D15: =CONCATENATE("0x", DEC2HEX(B15,2)) -> 0x0B | I15: SSO->MST 타워램프 BUZZER MUTE | L15: 11 | N15: =CONCATENATE("0x", DEC2HEX(L15,2)) -> 0x0B
B16: 12 | D16: =CONCATENATE("0x", DEC2HEX(B16,2)) -> 0x0C | L16: 12 | N16: =CONCATENATE("0x", DEC2HEX(L16,2)) -> 0x0C | S16: OP 비상탈출 눌림상태 | T16: 1 눌림, 0 정상 | U16: WMX Input 연동
B17: 13 | D17: =CONCATENATE("0x", DEC2HEX(B17,2)) -> 0x0D | L17: 13 | N17: =CONCATENATE("0x", DEC2HEX(L17,2)) -> 0x0D | S17: RM HP EMO 눌림상태 | T17: 1 눌림, 0 정상 | U17: Not Update
B18: 14 | D18: =CONCATENATE("0x", DEC2HEX(B18,2)) -> 0x0E | I18: SSO->MST 비상 정지 요구 | L18: 14 | N18: =CONCATENATE("0x", DEC2HEX(L18,2)) -> 0x0E | S18: RM OP EMO 눌림상태 | T18: 1 눌림, 0 정상 | U18: Not Update
B19: 15 | D19: =CONCATENATE("0x", DEC2HEX(B19,2)) -> 0x0F | I19: SSO->MST 에러 리셋 요구 | L19: 15 | N19: =CONCATENATE("0x", DEC2HEX(L19,2)) -> 0x0F | S19: RM Handy Touch EMO 눌림상태 | T19: 1 눌림, 0 정상 | U19: Not Update
A20: Not Update | B20: 16 | D20: =CONCATENATE("0x", DEC2HEX(B20,2)) -> 0x10 | I20: SSO->MST형광등 ON | K20: 2 | L20: 16 | N20: =CONCATENATE("0x", DEC2HEX(L20,2)) -> 0x10 | S20: MST->CIM형광등 ON 상태 | U20: Not Update
A21: Not Update | B21: 17 | D21: =CONCATENATE("0x", DEC2HEX(B21,2)) -> 0x11 | I21: SSO->MST형광등 OFF | L21: 17 | N21: =CONCATENATE("0x", DEC2HEX(L21,2)) -> 0x11
A22: Not Update | B22: 18 | D22: =CONCATENATE("0x", DEC2HEX(B22,2)) -> 0x12 | I22: SSO->MST형광등 시간적용 | L22: 18 | N22: =CONCATENATE("0x", DEC2HEX(L22,2)) -> 0x12
B23: 19 | D23: =CONCATENATE("0x", DEC2HEX(B23,2)) -> 0x13 | L23: 19 | N23: =CONCATENATE("0x", DEC2HEX(L23,2)) -> 0x13
B24: 20 | D24: =CONCATENATE("0x", DEC2HEX(B24,2)) -> 0x14 | L24: 20 | N24: =CONCATENATE("0x", DEC2HEX(L24,2)) -> 0x14
B25: 21 | D25: =CONCATENATE("0x", DEC2HEX(B25,2)) -> 0x15 | L25: 21 | N25: =CONCATENATE("0x", DEC2HEX(L25,2)) -> 0x15
B26: 22 | D26: =CONCATENATE("0x", DEC2HEX(B26,2)) -> 0x16 | L26: 22 | N26: =CONCATENATE("0x", DEC2HEX(L26,2)) -> 0x16
B27: 23 | D27: =CONCATENATE("0x", DEC2HEX(B27,2)) -> 0x17 | L27: 23 | N27: =CONCATENATE("0x", DEC2HEX(L27,2)) -> 0x17
B28: 24 | D28: =CONCATENATE("0x", DEC2HEX(B28,2)) -> 0x18 | L28: 24 | N28: =CONCATENATE("0x", DEC2HEX(L28,2)) -> 0x18 | S28: CPS#1 RUN 상태 | U28: WMX Input 연동
B29: 25 | D29: =CONCATENATE("0x", DEC2HEX(B29,2)) -> 0x19 | L29: 25 | N29: =CONCATENATE("0x", DEC2HEX(L29,2)) -> 0x19 | S29: CPS#1 ERROR 상태 | U29: WMX Input 연동
B30: 26 | D30: =CONCATENATE("0x", DEC2HEX(B30,2)) -> 0x1A | L30: 26 | N30: =CONCATENATE("0x", DEC2HEX(L30,2)) -> 0x1A | S30: CPS#1 FAILOVER 상태
B31: 27 | D31: =CONCATENATE("0x", DEC2HEX(B31,2)) -> 0x1B | L31: 27 | N31: =CONCATENATE("0x", DEC2HEX(L31,2)) -> 0x1B
B32: 28 | D32: =CONCATENATE("0x", DEC2HEX(B32,2)) -> 0x1C | L32: 28 | N32: =CONCATENATE("0x", DEC2HEX(L32,2)) -> 0x1C
B33: 29 | D33: =CONCATENATE("0x", DEC2HEX(B33,2)) -> 0x1D | L33: 29 | N33: =CONCATENATE("0x", DEC2HEX(L33,2)) -> 0x1D | S33: CPS#2 RUN 상태
B34: 30 | D34: =CONCATENATE("0x", DEC2HEX(B34,2)) -> 0x1E | L34: 30 | N34: =CONCATENATE("0x", DEC2HEX(L34,2)) -> 0x1E | S34: CPS#2 ERROR 상태
B35: 31 | D35: =CONCATENATE("0x", DEC2HEX(B35,2)) -> 0x1F | L35: 31 | N35: =CONCATENATE("0x", DEC2HEX(L35,2)) -> 0x1F | S35: CPS#2 FAILOVER 상태
B36: 32 | D36: =CONCATENATE("0x", DEC2HEX(B36,2)) -> 0x20 | K36: 3 | L36: 32 | N36: =CONCATENATE("0x", DEC2HEX(L36,2)) -> 0x20
B37: 33 | D37: =CONCATENATE("0x", DEC2HEX(B37,2)) -> 0x21 | I37: SS-One > MST CPS#1 Power On Enable | L37: 33 | N37: =CONCATENATE("0x", DEC2HEX(L37,2)) -> 0x21 | S37: MST > SS-One CPS#1 Power On Enable Lamp
B38: 34 | D38: =CONCATENATE("0x", DEC2HEX(B38,2)) -> 0x22 | L38: 34 | N38: =CONCATENATE("0x", DEC2HEX(L38,2)) -> 0x22 | S38: MST > SS-One CPS#1 1st Run Lamp
B39: 35 | D39: =CONCATENATE("0x", DEC2HEX(B39,2)) -> 0x23 | L39: 35 | N39: =CONCATENATE("0x", DEC2HEX(L39,2)) -> 0x23
B40: 36 | D40: =CONCATENATE("0x", DEC2HEX(B40,2)) -> 0x24 | L40: 36 | N40: =CONCATENATE("0x", DEC2HEX(L40,2)) -> 0x24
...

Sheet SS-One Word Communication
C1: SS-One <--> MST Communication Word Map
B2: Master Program Comment | C2: [SS-One] --> [Master] | J2: Comment | K2: 비고 | L2: Word Group | M2: [Master] --> [SS-One] | T2: Comment | U2: 비고 | V2: Master Program Comment
C3: Dec | M3: Dec
C4: 0 | E4: =CONCATENATE("0x", DEC2HEX(C4,2)) -> 0x00 | L4: 1 | M4: 0 | O4: =CONCATENATE("0x", DEC2HEX(M4,2)) -> 0x00 | T4: MST > SS-ONE 에러워 드<******> | V4: Alarm List 중 Master 영역 Word Insert
C5: 1 | E5: =CONCATENATE("0x", DEC2HEX(C5,2)) -> 0x01 | M5: 1 | O5: =CONCATENATE("0x", DEC2HEX(M5,2)) -> 0x01 | T5: MST > SS-ONE 에러워 드<******> | V5: Alarm List 중 Master 영역 Word Insert
C6: 2 | E6: =CONCATENATE("0x", DEC2HEX(C6,2)) -> 0x02 | M6: 2 | O6: =CONCATENATE("0x", DEC2HEX(M6,2)) -> 0x02 | T6: MST > SS-ONE 에러워 드<******> | V6: Alarm List 중 Master 영역 Word Insert
C7: 3 | E7: =CONCATENATE("0x", DEC2HEX(C7,2)) -> 0x03 | M7: 3 | O7: =CONCATENATE("0x", DEC2HEX(M7,2)) -> 0x03 | T7: MST > SS-ONE 에러워 드<******> | V7: Alarm List 중 Master 영역 Word Insert
C8: 4 | E8: =CONCATENATE("0x", DEC2HEX(C8,2)) -> 0x04 | M8: 4 | O8: =CONCATENATE("0x", DEC2HEX(M8,2)) -> 0x04 | T8: MST > SS-ONE 에러워 드<******> | V8: Alarm List 중 Master 영역 Word Insert
C9: 5 | E9: =CONCATENATE("0x", DEC2HEX(C9,2)) -> 0x05 | M9: 5 | O9: =CONCATENATE("0x", DEC2HEX(M9,2)) -> 0x05 | T9: MST > SS-ONE 에러워 드<******> | V9: Alarm List 중 Master 영역 Word Insert
C10: 6 | E10: =CONCATENATE("0x", DEC2HEX(C10,2)) -> 0x06 | M10: 6 | O10: =CONCATENATE("0x", DEC2HEX(M10,2)) -> 0x06 | T10: MST > SS-ONE 에러워 드<******> | V10: Alarm List 중 Master 영역 Word Insert
C11: 7 | E11: =CONCATENATE("0x", DEC2HEX(C11,2)) -> 0x07 | M11: 7 | O11: =CONCATENATE("0x", DEC2HEX(M11,2)) -> 0x07
C12: 8 | E12: =CONCATENATE("0x", DEC2HEX(C12,2)) -> 0x08 | M12: 8 | O12: =CONCATENATE("0x", DEC2HEX(M12,2)) -> 0x08 | T12: MST > SS-ONE CPS#1 1st 에러워드 | V12: Synustech 회신 (CPS Error Word는 어디서 받아오는 지?) CPS 에러워드는 CPS Type 에서 사용됩니다. 해당 코멘트 및 영역은 AlarmList(RM)영역에 추가하였습니다. (추후 Silicon Box CPS 사용시 활성화)
C13: 9 | E13: =CONCATENATE("0x", DEC2HEX(C13,2)) -> 0x09 | M13: 9 | O13: =CONCATENATE("0x", DEC2HEX(M13,2)) -> 0x09 | T13: MST > SS-ONE CPS#1 1st 에러워드
C14: 10 | E14: =CONCATENATE("0x", DEC2HEX(C14,2)) -> 0x0A | M14: 10 | O14: =CONCATENATE("0x", DEC2HEX(M14,2)) -> 0x0A | T14: MST > SS-ONE CPS#1 1st 에러워드
C15: 11 | E15: =CONCATENATE("0x", DEC2HEX(C15,2)) -> 0x0B | M15: 11 | O15: =CONCATENATE("0x", DEC2HEX(M15,2)) -> 0x0B | T15: MST > SS-ONE CPS#1 1st 에러워드
C16: 12 | E16: =CONCATENATE("0x", DEC2HEX(C16,2)) -> 0x0C | M16: 12 | O16: =CONCATENATE("0x", DEC2HEX(M16,2)) -> 0x0C | T16: MST > SS-ONE CPS#1 1st 에러워드
C17: 13 | E17: =CONCATENATE("0x", DEC2HEX(C17,2)) -> 0x0D | M17: 13 | O17: =CONCATENATE("0x", DEC2HEX(M17,2)) -> 0x0D | T17: MST > SS-ONE CPS#1 1st 에러워드
C18: 14 | E18: =CONCATENATE("0x", DEC2HEX(C18,2)) -> 0x0E | M18: 14 | O18: =CONCATENATE("0x", DEC2HEX(M18,2)) -> 0x0E | T18: MST > SS-ONE CPS#1 1st 에러워드
C19: 15 | E19: =CONCATENATE("0x", DEC2HEX(C19,2)) -> 0x0F | M19: 15 | O19: =CONCATENATE("0x", DEC2HEX(M19,2)) -> 0x0F
C20: 16 | E20: =CONCATENATE("0x", DEC2HEX(C20,2)) -> 0x10 | L20: 2 | M20: 16 | O20: =CONCATENATE("0x", DEC2HEX(M20,2)) -> 0x10
C21: 17 | E21: =CONCATENATE("0x", DEC2HEX(C21,2)) -> 0x11 | M21: 17 | O21: =CONCATENATE("0x", DEC2HEX(M21,2)) -> 0x11
C22: 18 | E22: =CONCATENATE("0x", DEC2HEX(C22,2)) -> 0x12 | M22: 18 | O22: =CONCATENATE("0x", DEC2HEX(M22,2)) -> 0x12
C23: 19 | E23: =CONCATENATE("0x", DEC2HEX(C23,2)) -> 0x13 | M23: 19 | O23: =CONCATENATE("0x", DEC2HEX(M23,2)) -> 0x13
C24: 20 | E24: =CONCATENATE("0x", DEC2HEX(C24,2)) -> 0x14 | M24: 20 | O24: =CONCATENATE("0x", DEC2HEX(M24,2)) -> 0x14
C25: 21 | E25: =CONCATENATE("0x", DEC2HEX(C25,2)) -> 0x15 | M25: 21 | O25: =CONCATENATE("0x", DEC2HEX(M25,2)) -> 0x15
C26: 22 | E26: =CONCATENATE("0x", DEC2HEX(C26,2)) -> 0x16 | M26: 22 | O26: =CONCATENATE("0x", DEC2HEX(M26,2)) -> 0x16
C27: 23 | E27: =CONCATENATE("0x", DEC2HEX(C27,2)) -> 0x17 | M27: 23 | O27: =CONCATENATE("0x", DEC2HEX(M27,2)) -> 0x17
C28: 24 | E28: =CONCATENATE("0x", DEC2HEX(C28,2)) -> 0x18 | M28: 24 | O28: =CONCATENATE("0x", DEC2HEX(M28,2)) -> 0x18
C29: 25 | E29: =CONCATENATE("0x", DEC2HEX(C29,2)) -> 0x19 | M29: 25 | O29: =CONCATENATE("0x", DEC2HEX(M29,2)) -> 0x19
C30: 26 | E30: =CONCATENATE("0x", DEC2HEX(C30,2)) -> 0x1A | M30: 26 | O30: =CONCATENATE("0x", DEC2HEX(M30,2)) -> 0x1A
C31: 27 | E31: =CONCATENATE("0x", DEC2HEX(C31,2)) -> 0x1B | M31: 27 | O31: =CONCATENATE("0x", DEC2HEX(M31,2)) -> 0x1B
C32: 28 | E32: =CONCATENATE("0x", DEC2HEX(C32,2)) -> 0x1C | M32: 28 | O32: =CONCATENATE("0x", DEC2HEX(M32,2)) -> 0x1C
... C35: 31 | E35: =CONCATENATE("0x", DEC2HEX(C35,2)) -> 0x1F | M35: 31 | O35: =CONCATENATE("0x", DEC2HEX(M35,2)) -> 0x1F
C36: 32 | E36: =CONCATENATE("0x", DEC2HEX(C36,2)) -> 0x20 | L36: 3 | M36: 32 | O36: =CONCATENATE("0x", DEC2HEX(M36,2)) -> 0x20
C37: 33 | E37: =CONCATENATE("0x", DEC2HEX(C37,2)) -> 0x21 | M37: 33 | O37: =CONCATENATE("0x", DEC2HEX(M37,2)) -> 0x21
C38: 34 | E38: =CONCATENATE("0x", DEC2HEX(C38,2)) -> 0x22 | M38: 34 | O38: =CONCATENATE("0x", DEC2HEX(M38,2)) -> 0x22
C39: 35 | E39: =CONCATENATE("0x", DEC2HEX(C39,2)) -> 0x23 | M39: 35 | O39: =CONCATENATE("0x", DEC2HEX(M39,2)) -> 0x23
C40: 36 | E40: =CONCATENATE("0x", DEC2HEX(C40,2)) -> 0x24 | M40: 36 | O40: =CONCATENATE("0x", DEC2HEX(M40,2)) -> 0x24
C41: 37 | E41: =CONCATENATE("0x", DEC2HEX(C41,2)) -> 0x25 | M41: 37 | O41: =CONCATENATE("0x", DEC2HEX(M41,2)) -> 0x25
C42: 38 | E42: =CONCATENATE("0x", DEC2HEX(C42,2)) -> 0x26 | M42: 38 | O42: =CONCATENATE("0x", DEC2HEX(M42,2)) -> 0x26
...

Sheet Port Bit
G1: Offset | H1: =HEX2DEC(40) -> 64
C2: SSONE -> CV | F2: EQP | G2: 30101 | H2: 30102 | I2: 30103 | J2: 30104 | K2: 30201 | L2: 30202 | M2: 30203 | N2: 30204 | O2: 30301 | P2: 30302 | Q2: 30303 | R2: 30304 | S2: 30501 | T2: 30502 | U2: 30503 | V2: …
F3: DP-Fosb | G3: MGV IN (AGV기능포함) | H3: MGV OUT (AGV기능포함) | I3: AGV IN | J3: AGV OUT | K3: OHT IN (MGV기능포함) | L3: OHT OUT (MGV기능포함) | M3: OHT IN (MGV기능포함) | N3: OHT OUT (MGV기능포함) | O3: AUTO IN | P3: AUTO IN | Q3: AUTO OUT | R3: AUTO OUT | S3: EQ | T3: EQ | U3: EQ
F4: DP-Wafer | G4: MGV IN | H4: MGV OUT | I4: AGV IN | J4: AGV OUT | K4: OHT IN (MGV기능포함) | L4: OHT OUT (MGV기능포함) | M4: OHT IN (MGV기능포함) | N4: OHT OUT (MGV기능포함) | O4: AUTO IN | P4: AUTO IN | Q4: AUTO OUT | R4: AUTO OUT | S4: EQ | T4: EQ | U4: EQ
F5: RECON-CST | G5: MGV IN (AGV기능포함) | H5: MGV OUT (AGV기능포함) | I5: AGV IN | J5: AGV OUT | K5: OHT IN (MGV기능포함) | L5: OHT OUT (MGV기능포함) | M5: OHT IN (MGV기능포함) | N5: OHT OUT (MGV기능포함) | O5: AUTO IN | P5: AUTO IN | Q5: AUTO OUT | R5: AUTO OUT | S5: EQ | T5: EQ | U5: EQ
F6: RECON-OVEN | G6: MGV IN (AGV기능포함) | H6: MGV OUT (AGV기능포함) | I6: AGV IN | J6: AGV OUT | K6: OHT IN (MGV기능포함) | L6: OHT OUT (MGV기능포함) | M6: OHT IN (MGV기능포함) | N6: OHT OUT (MGV기능포함) | O6: AUTO IN | P6: AUTO IN | Q6: AUTO OUT | R6: AUTO OUT | S6: EQ | T6: EQ | U6: EQ
F7: RDL-FOUP | G7: MGV IN (AGV기능포함) | H7: MGV OUT (AGV기능포함) | I7: AGV IN | J7: AGV OUT | K7: OHT IN (MGV기능포함) | L7: OHT OUT (MGV기능포함) | M7: OHT IN (MGV기능포함) | N7: OHT OUT (MGV기능포함) | O7: AUTO IN | P7: AUTO IN | Q7: AUTO OUT | R7: AUTO OUT | S7: EQ | T7: EQ | U7: EQ
B8: 추가 예정 항목 | F8: RDL-OVEN | G8: MGV IN (AGV기능포함) | H8: MGV OUT (AGV기능포함) | I8: AGV IN | J8: AGV OUT | K8: OHT IN (MGV기능포함) | L8: OHT OUT (MGV기능포함) | M8: OHT IN (MGV기능포함) | N8: OHT OUT (MGV기능포함) | O8: AUTO IN | P8: AUTO IN | Q8: AUTO OUT | R8: AUTO OUT | S8: EQ | T8: EQ | U8: EQ
F9: EOL-CST | G9: MGV IN (AGV기능포함) | H9: MGV OUT (AGV기능포함) | I9: AGV IN | J9: AGV OUT | K9: OHT IN (MGV기능포함) | L9: OHT OUT (MGV기능포함) | M9: OHT IN (MGV기능포함) | N9: OHT OUT (MGV기능포함) | O9: AUTO IN | P9: AUTO IN | Q9: AUTO OUT | R9: AUTO OUT | S9: EQ | T9: EQ | U9: EQ
F10: DIE BANK | G10: MGV IN (AGV기능포함) | H10: MGV OUT (AGV기능포함) | I10: AGV IN | J10: AGV OUT | K10: OHT IN (MGV기능포함) | L10: OHT OUT (MGV기능포함) | M10: OHT IN (MGV기능포함) | N10: OHT OUT (MGV기능포함) | O10: AUTO IN | P10: AUTO IN | Q10: AUTO OUT | R10: AUTO OUT | S10: EQ | T10: EQ | U10: EQ
B11: Master Program Comment | C11: Comment | D11: Description | E11: DEC | F11: Bit Per Word | G11: STK->PORT | H11: STK->PORT | I11: STK->PORT | J11: STK->PORT | K11: STK->PORT | L11: STK->PORT | M11: STK->PORT | N11: STK->PORT | O11: STK->PORT | P11: STK->PORT | Q11: STK->PORT | R11: STK->PORT | S11: STK->PORT | T11: STK->PORT | U11: STK->PORT
B12: RM에서 수신한 정보와 (RM From ID or RM To ID)가 (Port ID)와 일치하면 [CIM -> Port Bit Map] 업데이트 ([RM -> CIM bit D0 ~ d3] 을 [CIM -> Port bit Map 0 ~ 3]에 Write)(Master Mode인 경우만) | C12: TR-REQ | E12: 0 | F12: 1 | G12: =CONCATENATE("0x",DEC2HEX(E12,4)) -> 0x0000 | H12: =CONCATENATE("0x",DEC2HEX(E12 + (64 * 1),4)) -> 0x0040 | I12: =CONCATENATE("0x",DEC2HEX(E12 + (64 * 2),4)) -> 0x0080 | J12: =CONCATENATE("0x",DEC2HEX(E12 + (64 * 3),4)) -> 0x00C0 | K12: =CONCATENATE("0x",DEC2HEX(E12 + (64 * 4),4)) -> 0x0100 | L12: =CONCATENATE("0x",DEC2HEX(E12 + (64 * 5),4)) -> 0x0140 | M12: =CONCATENATE("0x",DEC2HEX(E12 + (64 * 6),4)) -> 0x0180 | N12: =CONCATENATE("0x",DEC2HEX(E12 + (64 * 7),4)) -> 0x01C0 | O12: =CONCATENATE("0x",DEC2HEX(E12 + (64 * 8),4)) -> 0x0200 | P12: =CONCATENATE("0x",DEC2HEX(E12 + (64 * 9),4)) -> 0x0240 | Q12: =CONCATENATE("0x",DEC2HEX(E12 + (64 * 10),4)) -> 0x0280 | R12: =CONCATENATE("0x",DEC2HEX(E12 + (64 * 11),4)) -> 0x02C0 | S12: =CONCATENATE("0x",DEC2HEX(E12 + (64 * 12),4)) -> 0x0300 | T12: =CONCATENATE("0x",DEC2HEX(E12 + (64 * 13),4)) -> 0x0340 | U12: =CONCATENATE("0x",DEC2HEX(E12 + (64 * 14),4)) -> 0x0380
C13: BUSY | E13: 1 | G13: =CONCATENATE("0x",DEC2HEX(E13,4)) -> 0x0001 | H13: =CONCATENATE("0x",DEC2HEX(E13 + (64 * 1),4)) -> 0x0041 | I13: =CONCATENATE("0x",DEC2HEX(E13 + (64 * 2),4)) -> 0x0081 | J13: =CONCATENATE("0x",DEC2HEX(E13 + (64 * 3),4)) -> 0x00C1 | K13: =CONCATENATE("0x",DEC2HEX(E13 + (64 * 4),4)) -> 0x0101 | L13: =CONCATENATE("0x",DEC2HEX(E13 + (64 * 5),4)) -> 0x0141 | M13: =CONCATENATE("0x",DEC2HEX(E13 + (64 * 6),4)) -> 0x0181 | N13: =CONCATENATE("0x",DEC2HEX(E13 + (64 * 7),4)) -> 0x01C1 | O13: =CONCATENATE("0x",DEC2HEX(E13 + (64 * 8),4)) -> 0x0201 | P13: =CONCATENATE("0x",DEC2HEX(E13 + (64 * 9),4)) -> 0x0241 | Q13: =CONCATENATE("0x",DEC2HEX(E13 + (64 * 10),4)) -> 0x0281 | R13: =CONCATENATE("0x",DEC2HEX(E13 + (64 * 11),4)) -> 0x02C1 | S13: =CONCATENATE("0x",DEC2HEX(E13 + (64 * 12),4)) -> 0x0301 | T13: =CONCATENATE("0x",DEC2HEX(E13 + (64 * 13),4)) -> 0x0341 | U13: =CONCATENATE("0x",DEC2HEX(E13 + (64 * 14),4)) -> 0x0381
C14: COMPLETE | E14: 2 | G14: =CONCATENATE("0x",DEC2HEX(E14,4)) -> 0x0002 | H14: =CONCATENATE("0x",DEC2HEX(E14 + (64 * 1),4)) -> 0x0042 | I14: =CONCATENATE("0x",DEC2HEX(E14 + (64 * 2),4)) -> 0x0082 | J14: =CONCATENATE("0x",DEC2HEX(E14 + (64 * 3),4)) -> 0x00C2 | K14: =CONCATENATE("0x",DEC2HEX(E14 + (64 * 4),4)) -> 0x0102 | L14: =CONCATENATE("0x",DEC2HEX(E14 + (64 * 5),4)) -> 0x0142 | M14: =CONCATENATE("0x",DEC2HEX(E14 + (64 * 6),4)) -> 0x0182 | N14: =CONCATENATE("0x",DEC2HEX(E14 + (64 * 7),4)) -> 0x01C2 | O14: =CONCATENATE("0x",DEC2HEX(E14 + (64 * 8),4)) -> 0x0202 | P14: =CONCATENATE("0x",DEC2HEX(E14 + (64 * 9),4)) -> 0x0242 | Q14: =CONCATENATE("0x",DEC2HEX(E14 + (64 * 10),4)) -> 0x0282 | R14: =CONCATENATE("0x",DEC2HEX(E14 + (64 * 11),4)) -> 0x02C2 | S14: =CONCATENATE("0x",DEC2HEX(E14 + (64 * 12),4)) -> 0x0302 | T14: =CONCATENATE("0x",DEC2HEX(E14 + (64 * 13),4)) -> 0x0342 | U14: =CONCATENATE("0x",DEC2HEX(E14 + (64 * 14),4)) -> 0x0382
C15: STK ERROR | E15: 3 | G15: =CONCATENATE("0x",DEC2HEX(E15,4)) -> 0x0003 | H15: =CONCATENATE("0x",DEC2HEX(E15 + (64 * 1),4)) -> 0x0043 | I15: =CONCATENATE("0x",DEC2HEX(E15 + (64 * 2),4)) -> 0x0083 | J15: =CONCATENATE("0x",DEC2HEX(E15 + (64 * 3),4)) -> 0x00C3 | K15: =CONCATENATE("0x",DEC2HEX(E15 + (64 * 4),4)) -> 0x0103 | L15: =CONCATENATE("0x",DEC2HEX(E15 + (64 * 5),4)) -> 0x0143 | M15: =CONCATENATE("0x",DEC2HEX(E15 + (64 * 6),4)) -> 0x0183 | N15: =CONCATENATE("0x",DEC2HEX(E15 + (64 * 7),4)) -> 0x01C3 | O15: =CONCATENATE("0x",DEC2HEX(E15 + (64 * 8),4)) -> 0x0203 | P15: =CONCATENATE("0x",DEC2HEX(E15 + (64 * 9),4)) -> 0x0243 | Q15: =CONCATENATE("0x",DEC2HEX(E15 + (64 * 10),4)) -> 0x0283 | R15: =CONCATENATE("0x",DEC2HEX(E15 + (64 * 11),4)) -> 0x02C3 | S15: =CONCATENATE("0x",DEC2HEX(E15 + (64 * 12),4)) -> 0x0303 | T15: =CONCATENATE("0x",DEC2HEX(E15 + (64 * 13),4)) -> 0x0343 | U15: =CONCATENATE("0x",DEC2HEX(E15 + (64 * 14),4)) -> 0x0383
C16: RESERVED | E16: 4 | G16: =CONCATENATE("0x",DEC2HEX(E16,4)) -> 0x0004 | H16: =CONCATENATE("0x",DEC2HEX(E16 + (64 * 1),4)) -> 0x0044 | I16: =CONCATENATE("0x",DEC2HEX(E16 + (64 * 2),4)) -> 0x0084 | J16: =CONCATENATE("0x",DEC2HEX(E16 + (64 * 3),4)) -> 0x00C4 | K16: =CONCATENATE("0x",DEC2HEX(E16 + (64 * 4),4)) -> 0x0104 | L16: =CONCATENATE("0x",DEC2HEX(E16 + (64 * 5),4)) -> 0x0144 | M16: =CONCATENATE("0x",DEC2HEX(E16 + (64 * 6),4)) -> 0x0184 | N16: =CONCATENATE("0x",DEC2HEX(E16 + (64 * 7),4)) -> 0x01C4 | O16: =CONCATENATE("0x",DEC2HEX(E16 + (64 * 8),4)) -> 0x0204 | P16: =CONCATENATE("0x",DEC2HEX(E16 + (64 * 9),4)) -> 0x0244 | Q16: =CONCATENATE("0x",DEC2HEX(E16 + (64 * 10),4)) -> 0x0284 | R16: =CONCATENATE("0x",DEC2HEX(E16 + (64 * 11),4)) -> 0x02C4 | S16: =CONCATENATE("0x",DEC2HEX(E16 + (64 * 12),4)) -> 0x0304 | T16: =CONCATENATE("0x",DEC2HEX(E16 + (64 * 13),4)) -> 0x0344 | U16: =CONCATENATE("0x",DEC2HEX(E16 + (64 * 14),4)) -> 0x0384
C17: OUTPUT REQ | E17: 5 | G17: =CONCATENATE("0x",DEC2HEX(E17,4)) -> 0x0005 | H17: =CONCATENATE("0x",DEC2HEX(E17 + (64 * 1),4)) -> 0x0045 | I17: =CONCATENATE("0x",DEC2HEX(E17 + (64 * 2),4)) -> 0x0085 | J17: =CONCATENATE("0x",DEC2HEX(E17 + (64 * 3),4)) -> 0x00C5 | K17: =CONCATENATE("0x",DEC2HEX(E17 + (64 * 4),4)) -> 0x0105 | L17: =CONCATENATE("0x",DEC2HEX(E17 + (64 * 5),4)) -> 0x0145 | M17: =CONCATENATE("0x",DEC2HEX(E17 + (64 * 6),4)) -> 0x0185 | N17: =CONCATENATE("0x",DEC2HEX(E17 + (64 * 7),4)) -> 0x01C5 | O17: =CONCATENATE("0x",DEC2HEX(E17 + (64 * 8),4)) -> 0x0205 | P17: =CONCATENATE("0x",DEC2HEX(E17 + (64 * 9),4)) -> 0x0245 | Q17: =CONCATENATE("0x",DEC2HEX(E17 + (64 * 10),4)) -> 0x0285 | R17: =CONCATENATE("0x",DEC2HEX(E17 + (64 * 11),4)) -> 0x02C5 | S17: =CONCATENATE("0x",DEC2HEX(E17 + (64 * 12),4)) -> 0x0305 | T17: =CONCATENATE("0x",DEC2HEX(E17 + (64 * 13),4)) -> 0x0345 | U17: =CONCATENATE("0x",DEC2HEX(E17 + (64 * 14),4)) -> 0x0385
C18: RESERVED | E18: 6 | G18: =CONCATENATE("0x",DEC2HEX(E18,4)) -> 0x0006 | H18: =CONCATENATE("0x",DEC2HEX(E18 + (64 * 1),4)) -> 0x0046 | I18: =CONCATENATE("0x",DEC2HEX(E18 + (64 * 2),4)) -> 0x0086 | J18: =CONCATENATE("0x",DEC2HEX(E18 + (64 * 3),4)) -> 0x00C6 | K18: =CONCATENATE("0x",DEC2HEX(E18 + (64 * 4),4)) -> 0x0106 | L18: =CONCATENATE("0x",DEC2HEX(E18 + (64 * 5),4)) -> 0x0146 | M18: =CONCATENATE("0x",DEC2HEX(E18 + (64 * 6),4)) -> 0x0186 | N18: =CONCATENATE("0x",DEC2HEX(E18 + (64 * 7),4)) -> 0x01C6 | O18: =CONCATENATE("0x",DEC2HEX(E18 + (64 * 8),4)) -> 0x0206 | P18: =CONCATENATE("0x",DEC2HEX(E18 + (64 * 9),4)) -> 0x0246 | Q18: =CONCATENATE("0x",DEC2HEX(E18 + (64 * 10),4)) -> 0x0286 | R18: =CONCATENATE("0x",DEC2HEX(E18 + (64 * 11),4)) -> 0x02C6 | S18: =CONCATENATE("0x",DEC2HEX(E18 + (64 * 12),4)) -> 0x0306 | T18: =CONCATENATE("0x",DEC2HEX(E18 + (64 * 13),4)) -> 0x0346 | U18: =CONCATENATE("0x",DEC2HEX(E18 + (64 * 14),4)) -> 0x0386
B19: RM 반송 진행중 (별 다른 체크 루틴 없음) | C19: TRANSFERLING | E19: 7 | G19: =CONCATENATE("0x",DEC2HEX(E19,4)) -> 0x0007 | H19: =CONCATENATE("0x",DEC2HEX(E19 + (64 * 1),4)) -> 0x0047 | I19: =CONCATENATE("0x",DEC2HEX(E19 + (64 * 2),4)) -> 0x0087 | J19: =CONCATENATE("0x",DEC2HEX(E19 + (64 * 3),4)) -> 0x00C7 | K19: =CONCATENATE("0x",DEC2HEX(E19 + (64 * 4),4)) -> 0x0107 | L19: =CONCATENATE("0x",DEC2HEX(E19 + (64 * 5),4)) -> 0x0147 | M19: =CONCATENATE("0x",DEC2HEX(E19 + (64 * 6),4)) -> 0x0187 | N19: =CONCATENATE("0x",DEC2HEX(E19 + (64 * 7),4)) -> 0x01C7 | O19: =CONCATENATE("0x",DEC2HEX(E19 + (64 * 8),4)) -> 0x0207 | P19: =CONCATENATE("0x",DEC2HEX(E19 + (64 * 9),4)) -> 0x0247 | Q19: =CONCATENATE("0x",DEC2HEX(E19 + (64 * 10),4)) -> 0x0287 | R19: =CONCATENATE("0x",DEC2HEX(E19 + (64 * 11),4)) -> 0x02C7 | S19: =CONCATENATE("0x",DEC2HEX(E19 + (64 * 12),4)) -> 0x0307 | T19: =CONCATENATE("0x",DEC2HEX(E19 + (64 * 13),4)) -> 0x0347 | U19: =CONCATENATE("0x",DEC2HEX(E19 + (64 * 14),4)) -> 0x0387
C20: LIGHT CURTIAN | E20: 8 | G20: =CONCATENATE("0x",DEC2HEX(E20,4)) -> 0x0008 | H20: =CONCATENATE("0x",DEC2HEX(E20 + (64 * 1),4)) -> 0x0048 | I20: =CONCATENATE("0x",DEC2HEX(E20 + (64 * 2),4)) -> 0x0088 | J20: =CONCATENATE("0x",DEC2HEX(E20 + (64 * 3),4)) -> 0x00C8 | K20: =CONCATENATE("0x",DEC2HEX(E20 + (64 * 4),4)) -> 0x0108 | L20: =CONCATENATE("0x",DEC2HEX(E20 + (64 * 5),4)) -> 0x0148 | M20: =CONCATENATE("0x",DEC2HEX(E20 + (64 * 6),4)) -> 0x0188 | N20: =CONCATENATE("0x",DEC2HEX(E20 + (64 * 7),4)) -> 0x01C8 | O20: =CONCATENATE("0x",DEC2HEX(E20 + (64 * 8),4)) -> 0x0208 | P20: =CONCATENATE("0x",DEC2HEX(E20 + (64 * 9),4)) -> 0x0248 | Q20: =CONCATENATE("0x",DEC2HEX(E20 + (64 * 10),4)) -> 0x0288 | R20: =CONCATENATE("0x",DEC2HEX(E20 + (64 * 11),4)) -> 0x02C8 | S20: =CONCATENATE("0x",DEC2HEX(E20 + (64 * 12),4)) -> 0x0308 | T20: =CONCATENATE("0x",DEC2HEX(E20 + (64 * 13),4)) -> 0x0348 | U20: =CONCATENATE("0x",DEC2HEX(E20 + (64 * 14),4)) -> 0x0388
C21: RESERVED | E21: 9 | G21: =CONCATENATE("0x",DEC2HEX(E21,4)) -> 0x0009 | H21: =CONCATENATE("0x",DEC2HEX(E21 + (64 * 1),4)) -> 0x0049 | I21: =CONCATENATE("0x",DEC2HEX(E21 + (64 * 2),4)) -> 0x0089 | J21: =CONCATENATE("0x",DEC2HEX(E21 + (64 * 3),4)) -> 0x00C9 | K21: =CONCATENATE("0x",DEC2HEX(E21 + (64 * 4),4)) -> 0x0109 | L21: =CONCATENATE("0x",DEC2HEX(E21 + (64 * 5),4)) -> 0x0149 | M21: =CONCATENATE("0x",DEC2HEX(E21 + (64 * 6),4)) -> 0x0189 | N21: =CONCATENATE("0x",DEC2HEX(E21 + (64 * 7),4)) -> 0x01C9 | O21: =CONCATENATE("0x",DEC2HEX(E21 + (64 * 8),4)) -> 0x0209 | P21: =CONCATENATE("0x",DEC2HEX(E21 + (64 * 9),4)) -> 0x0249 | Q21: =CONCATENATE("0x",DEC2HEX(E21 + (64 * 10),4)) -> 0x0289 | R21: =CONCATENATE("0x",DEC2HEX(E21 + (64 * 11),4)) -> 0x02C9 | S21: =CONCATENATE("0x",DEC2HEX(E21 + (64 * 12),4)) -> 0x0309 | T21: =CONCATENATE("0x",DEC2HEX(E21 + (64 * 13),4)) -> 0x0349 | U21: =CONCATENATE("0x",DEC2HEX(E21 + (64 * 14),4)) -> 0x0389
C22: RESERVED | E22: 10 | G22: =CONCATENATE("0x",DEC2HEX(E22,4)) -> 0x000A | H22: =CONCATENATE("0x",DEC2HEX(E22 + (64 * 1),4)) -> 0x004A | I22: =CONCATENATE("0x",DEC2HEX(E22 + (64 * 2),4)) -> 0x008A | J22: =CONCATENATE("0x",DEC2HEX(E22 + (64 * 3),4)) -> 0x00CA | K22: =CONCATENATE("0x",DEC2HEX(E22 + (64 * 4),4)) -> 0x010A | L22: =CONCATENATE("0x",DEC2HEX(E22 + (64 * 5),4)) -> 0x014A | M22: =CONCATENATE("0x",DEC2HEX(E22 + (64 * 6),4)) -> 0x018A | N22: =CONCATENATE("0x",DEC2HEX(E22 + (64 * 7),4)) -> 0x01CA | O22: =CONCATENATE("0x",DEC2HEX(E22 + (64 * 8),4)) -> 0x020A | P22: =CONCATENATE("0x",DEC2HEX(E22 + (64 * 9),4)) -> 0x024A | Q22: =CONCATENATE("0x",DEC2HEX(E22 + (64 * 10),4)) -> 0x028A | R22: =CONCATENATE("0x",DEC2HEX(E22 + (64 * 11),4)) -> 0x02CA | S22: =CONCATENATE("0x",DEC2HEX(E22 + (64 * 12),4)) -> 0x030A | T22: =CONCATENATE("0x",DEC2HEX(E22 + (64 * 13),4)) -> 0x034A | U22: =CONCATENATE("0x",DEC2HEX(E22 + (64 * 14),4)) -> 0x038A
C23: RESERVED | E23: 11 | G23: =CONCATENATE("0x",DEC2HEX(E23,4)) -> 0x000B | H23: =CONCATENATE("0x",DEC2HEX(E23 + (64 * 1),4)) -> 0x004B | I23: =CONCATENATE("0x",DEC2HEX(E23 + (64 * 2),4)) -> 0x008B | J23: =CONCATENATE("0x",DEC2HEX(E23 + (64 * 3),4)) -> 0x00CB | K23: =CONCATENATE("0x",DEC2HEX(E23 + (64 * 4),4)) -> 0x010B | L23: =CONCATENATE("0x",DEC2HEX(E23 + (64 * 5),4)) -> 0x014B | M23: =CONCATENATE("0x",DEC2HEX(E23 + (64 * 6),4)) -> 0x018B | N23: =CONCATENATE("0x",DEC2HEX(E23 + (64 * 7),4)) -> 0x01CB | O23: =CONCATENATE("0x",DEC2HEX(E23 + (64 * 8),4)) -> 0x020B | P23: =CONCATENATE("0x",DEC2HEX(E23 + (64 * 9),4)) -> 0x024B | Q23: =CONCATENATE("0x",DEC2HEX(E23 + (64 * 10),4)) -> 0x028B | R23: =CONCATENATE("0x",DEC2HEX(E23 + (64 * 11),4)) -> 0x02CB | S23: =CONCATENATE("0x",DEC2HEX(E23 + (64 * 12),4)) -> 0x030B | T23: =CONCATENATE("0x",DEC2HEX(E23 + (64 * 13),4)) -> 0x034B | U23: =CONCATENATE("0x",DEC2HEX(E23 + (64 * 14),4)) -> 0x038B
C24: RESERVED | E24: 12 | G24: =CONCATENATE("0x",DEC2HEX(E24,4)) -> 0x000C | H24: =CONCATENATE("0x",DEC2HEX(E24 + (64 * 1),4)) -> 0x004C | I24: =CONCATENATE("0x",DEC2HEX(E24 + (64 * 2),4)) -> 0x008C | J24: =CONCATENATE("0x",DEC2HEX(E24 + (64 * 3),4)) -> 0x00CC | K24: =CONCATENATE("0x",DEC2HEX(E24 + (64 * 4),4)) -> 0x010C | L24: =CONCATENATE("0x",DEC2HEX(E24 + (64 * 5),4)) -> 0x014C | M24: =CONCATENATE("0x",DEC2HEX(E24 + (64 * 6),4)) -> 0x018C | N24: =CONCATENATE("0x",DEC2HEX(E24 + (64 * 7),4)) -> 0x01CC | O24: =CONCATENATE("0x",DEC2HEX(E24 + (64 * 8),4)) -> 0x020C | P24: =CONCATENATE("0x",DEC2HEX(E24 + (64 * 9),4)) -> 0x024C | Q24: =CONCATENATE("0x",DEC2HEX(E24 + (64 * 10),4)) -> 0x028C | R24: =CONCATENATE("0x",DEC2HEX(E24 + (64 * 11),4)) -> 0x02CC | S24: =CONCATENATE("0x",DEC2HEX(E24 + (64 * 12),4)) -> 0x030C | T24: =CONCATENATE("0x",DEC2HEX(E24 + (64 * 13),4)) -> 0x034C | U24: =CONCATENATE("0x",DEC2HEX(E24 + (64 * 14),4)) -> 0x038C
C25: RESERVED | E25: 13 | G25: =CONCATENATE("0x",DEC2HEX(E25,4)) -> 0x000D | H25: =CONCATENATE("0x",DEC2HEX(E25 + (64 * 1),4)) -> 0x004D | I25: =CONCATENATE("0x",DEC2HEX(E25 + (64 * 2),4)) -> 0x008D | J25: =CONCATENATE("0x",DEC2HEX(E25 + (64 * 3),4)) -> 0x00CD | K25: =CONCATENATE("0x",DEC2HEX(E25 + (64 * 4),4)) -> 0x010D | L25: =CONCATENATE("0x",DEC2HEX(E25 + (64 * 5),4)) -> 0x014D | M25: =CONCATENATE("0x",DEC2HEX(E25 + (64 * 6),4)) -> 0x018D | N25: =CONCATENATE("0x",DEC2HEX(E25 + (64 * 7),4)) -> 0x01CD | O25: =CONCATENATE("0x",DEC2HEX(E25 + (64 * 8),4)) -> 0x020D | P25: =CONCATENATE("0x",DEC2HEX(E25 + (64 * 9),4)) -> 0x024D | Q25: =CONCATENATE("0x",DEC2HEX(E25 + (64 * 10),4)) -> 0x028D | R25: =CONCATENATE("0x",DEC2HEX(E25 + (64 * 11),4)) -> 0x02CD | S25: =CONCATENATE("0x",DEC2HEX(E25 + (64 * 12),4)) -> 0x030D | T25: =CONCATENATE("0x",DEC2HEX(E25 + (64 * 13),4)) -> 0x034D | U25: =CONCATENATE("0x",DEC2HEX(E25 + (64 * 14),4)) -> 0x038D
C26: RESERVED | E26: 14 | G26: =CONCATENATE("0x",DEC2HEX(E26,4)) -> 0x000E | H26: =CONCATENATE("0x",DEC2HEX(E26 + (64 * 1),4)) -> 0x004E | I26: =CONCATENATE("0x",DEC2HEX(E26 + (64 * 2),4)) -> 0x008E | J26: =CONCATENATE("0x",DEC2HEX(E26 + (64 * 3),4)) -> 0x00CE | K26: =CONCATENATE("0x",DEC2HEX(E26 + (64 * 4),4)) -> 0x010E | L26: =CONCATENATE("0x",DEC2HEX(E26 + (64 * 5),4)) -> 0x014E | M26: =CONCATENATE("0x",DEC2HEX(E26 + (64 * 6),4)) -> 0x018E | N26: =CONCATENATE("0x",DEC2HEX(E26 + (64 * 7),4)) -> 0x01CE | O26: =CONCATENATE("0x",DEC2HEX(E26 + (64 * 8),4)) -> 0x020E | P26: =CONCATENATE("0x",DEC2HEX(E26 + (64 * 9),4)) -> 0x024E | Q26: =CONCATENATE("0x",DEC2HEX(E26 + (64 * 10),4)) -> 0x028E | R26: =CONCATENATE("0x",DEC2HEX(E26 + (64 * 11),4)) -> 0x02CE | S26: =CONCATENATE("0x",DEC2HEX(E26 + (64 * 12),4)) -> 0x030E | T26: =CONCATENATE("0x",DEC2HEX(E26 + (64 * 13),4)) -> 0x034E | U26: =CONCATENATE("0x",DEC2HEX(E26 + (64 * 14),4)) -> 0x038E
C27: RESERVED | E27: 15 | G27: =CONCATENATE("0x",DEC2HEX(E27,4)) -> 0x000F | H27: =CONCATENATE("0x",DEC2HEX(E27 + (64 * 1),4)) -> 0x004F | I27: =CONCATENATE("0x",DEC2HEX(E27 + (64 * 2),4)) -> 0x008F | J27: =CONCATENATE("0x",DEC2HEX(E27 + (64 * 3),4)) -> 0x00CF | K27: =CONCATENATE("0x",DEC2HEX(E27 + (64 * 4),4)) -> 0x010F | L27: =CONCATENATE("0x",DEC2HEX(E27 + (64 * 5),4)) -> 0x014F | M27: =CONCATENATE("0x",DEC2HEX(E27 + (64 * 6),4)) -> 0x018F | N27: =CONCATENATE("0x",DEC2HEX(E27 + (64 * 7),4)) -> 0x01CF | O27: =CONCATENATE("0x",DEC2HEX(E27 + (64 * 8),4)) -> 0x020F | P27: =CONCATENATE("0x",DEC2HEX(E27 + (64 * 9),4)) -> 0x024F | Q27: =CONCATENATE("0x",DEC2HEX(E27 + (64 * 10),4)) -> 0x028F | R27: =CONCATENATE("0x",DEC2HEX(E27 + (64 * 11),4)) -> 0x02CF | S27: =CONCATENATE("0x",DEC2HEX(E27 + (64 * 12),4)) -> 0x030F | T27: =CONCATENATE("0x",DEC2HEX(E27 + (64 * 13),4)) -> 0x034F | U27: =CONCATENATE("0x",DEC2HEX(E27 + (64 * 14),4)) -> 0x038F
C28: RESERVED | D28: CIM 지령 | E28: 16 | F28: 2 | G28: =CONCATENATE("0x",DEC2HEX(E28,4)) -> 0x0010 | H28: =CONCATENATE("0x",DEC2HEX(E28 + (64 * 1),4)) -> 0x0050 | I28: =CONCATENATE("0x",DEC2HEX(E28 + (64 * 2),4)) -> 0x0090 | J28: =CONCATENATE("0x",DEC2HEX(E28 + (64 * 3),4)) -> 0x00D0 | K28: =CONCATENATE("0x",DEC2HEX(E28 + (64 * 4),4)) -> 0x0110 | L28: =CONCATENATE("0x",DEC2HEX(E28 + (64 * 5),4)) -> 0x0150 | M28: =CONCATENATE("0x",DEC2HEX(E28 + (64 * 6),4)) -> 0x0190 | N28: =CONCATENATE("0x",DEC2HEX(E28 + (64 * 7),4)) -> 0x01D0 | O28: =CONCATENATE("0x",DEC2HEX(E28 + (64 * 8),4)) -> 0x0210 | P28: =CONCATENATE("0x",DEC2HEX(E28 + (64 * 9),4)) -> 0x0250 | Q28: =CONCATENATE("0x",DEC2HEX(E28 + (64 * 10),4)) -> 0x0290 | R28: =CONCATENATE("0x",DEC2HEX(E28 + (64 * 11),4)) -> 0x02D0 | S28: =CONCATENATE("0x",DEC2HEX(E28 + (64 * 12),4)) -> 0x0310 | T28: =CONCATENATE("0x",DEC2HEX(E28 + (64 * 13),4)) -> 0x0350 | U28: =CONCATENATE("0x",DEC2HEX(E28 + (64 * 14),4)) -> 0x0390
B29: Run Enable[Port->CIM bit 17] true 상태면 Auto Control Start() 실행 | C29: RUN REQ - CIM | E29: 17 | G29: =CONCATENATE("0x",DEC2HEX(E29,4)) -> 0x0011 | H29: =CONCATENATE("0x",DEC2HEX(E29 + (64 * 1),4)) -> 0x0051 | I29: =CONCATENATE("0x",DEC2HEX(E29 + (64 * 2),4)) -> 0x0091 | J29: =CONCATENATE("0x",DEC2HEX(E29 + (64 * 3),4)) -> 0x00D1 | K29: =CONCATENATE("0x",DEC2HEX(E29 + (64 * 4),4)) -> 0x0111 | L29: =CONCATENATE("0x",DEC2HEX(E29 + (64 * 5),4)) -> 0x0151 | M29: =CONCATENATE("0x",DEC2HEX(E29 + (64 * 6),4)) -> 0x0191 | N29: =CONCATENATE("0x",DEC2HEX(E29 + (64 * 7),4)) -> 0x01D1 | O29: =CONCATENATE("0x",DEC2HEX(E29 + (64 * 8),4)) -> 0x0211 | P29: =CONCATENATE("0x",DEC2HEX(E29 + (64 * 9),4)) -> 0x0251 | Q29: =CONCATENATE("0x",DEC2HEX(E29 + (64 * 10),4)) -> 0x0291 | R29: =CONCATENATE("0x",DEC2HEX(E29 + (64 * 11),4)) -> 0x02D1 | S29: =CONCATENATE("0x",DEC2HEX(E29 + (64 * 12),4)) -> 0x0311 | T29: =CONCATENATE("0x",DEC2HEX(E29 + (64 * 13),4)) -> 0x0351 | U29: =CONCATENATE("0x",DEC2HEX(E29 + (64 * 14),4)) -> 0x0391
B30: Stop Enable [Port->CIM bit 18] true 상태면 Stop Auto Control() | C30: STOP REQ - CIM | E30: 18 | G30: =CONCATENATE("0x",DEC2HEX(E30,4)) -> 0x0012 | H30: =CONCATENATE("0x",DEC2HEX(E30 + (64 * 1),4)) -> 0x0052 | I30: =CONCATENATE("0x",DEC2HEX(E30 + (64 * 2),4)) -> 0x0092 | J30: =CONCATENATE("0x",DEC2HEX(E30 + (64 * 3),4)) -> 0x00D2 | K30: =CONCATENATE("0x",DEC2HEX(E30 + (64 * 4),4)) -> 0x0112 | L30: =CONCATENATE("0x",DEC2HEX(E30 + (64 * 5),4)) -> 0x0152 | M30: =CONCATENATE("0x",DEC2HEX(E30 + (64 * 6),4)) -> 0x0192 | N30: =CONCATENATE("0x",DEC2HEX(E30 + (64 * 7),4)) -> 0x01D2 | O30: =CONCATENATE("0x",DEC2HEX(E30 + (64 * 8),4)) -> 0x0212 | P30: =CONCATENATE("0x",DEC2HEX(E30 + (64 * 9),4)) -> 0x0252 | Q30: =CONCATENATE("0x",DEC2HEX(E30 + (64 * 10),4)) -> 0x0292 | R30: =CONCATENATE("0x",DEC2HEX(E30 + (64 * 11),4)) -> 0x02D2 | S30: =CONCATENATE("0x",DEC2HEX(E30 + (64 * 12),4)) -> 0x0312 | T30: =CONCATENATE("0x",DEC2HEX(E30 + (64 * 13),4)) -> 0x0352 | U30: =CONCATENATE("0x",DEC2HEX(E30 + (64 * 14),4)) -> 0x0392
C31: RESERVED | E31: 19 | G31: =CONCATENATE("0x",DEC2HEX(E31,4)) -> 0x0013 | H31: =CONCATENATE("0x",DEC2HEX(E31 + (64 * 1),4)) -> 0x0053 | I31: =CONCATENATE("0x",DEC2HEX(E31 + (64 * 2),4)) -> 0x0093 | J31: =CONCATENATE("0x",DEC2HEX(E31 + (64 * 3),4)) -> 0x00D3 | K31: =CONCATENATE("0x",DEC2HEX(E31 + (64 * 4),4)) -> 0x0113 | L31: =CONCATENATE("0x",DEC2HEX(E31 + (64 * 5),4)) -> 0x0153 | M31: =CONCATENATE("0x",DEC2HEX(E31 + (64 * 6),4)) -> 0x0193 | N31: =CONCATENATE("0x",DEC2HEX(E31 + (64 * 7),4)) -> 0x01D3 | O31: =CONCATENATE("0x",DEC2HEX(E31 + (64 * 8),4)) -> 0x0213 | P31: =CONCATENATE("0x",DEC2HEX(E31 + (64 * 9),4)) -> 0x0253 | Q31: =CONCATENATE("0x",DEC2HEX(E31 + (64 * 10),4)) -> 0x0293 | R31: =CONCATENATE("0x",DEC2HEX(E31 + (64 * 11),4)) -> 0x02D3 | S31: =CONCATENATE("0x",DEC2HEX(E31 + (64 * 12),4)) -> 0x0313 | T31: =CONCATENATE("0x",DEC2HEX(E31 + (64 * 13),4)) -> 0x0353 | U31: =CONCATENATE("0x",DEC2HEX(E31 + (64 * 14),4)) -> 0x0393
B32: Power On Req [CIM -> Port bit 20] == true && Power On Enable [Port -> CIM bit 20] == true 면 Servo On | C32: POWE ON REQ - CIM | E32: 20 | G32: =CONCATENATE("0x",DEC2HEX(E32,4)) -> 0x0014 | H32: =CONCATENATE("0x",DEC2HEX(E32 + (64 * 1),4)) -> 0x0054 | I32: =CONCATENATE("0x",DEC2HEX(E32 + (64 * 2),4)) -> 0x0094 | J32: =CONCATENATE("0x",DEC2HEX(E32 + (64 * 3),4)) -> 0x00D4 | K32: =CONCATENATE("0x",DEC2HEX(E32 + (64 * 4),4)) -> 0x0114 | L32: =CONCATENATE("0x",DEC2HEX(E32 + (64 * 5),4)) -> 0x0154 | M32: =CONCATENATE("0x",DEC2HEX(E32 + (64 * 6),4)) -> 0x0194 | N32: =CONCATENATE("0x",DEC2HEX(E32 + (64 * 7),4)) -> 0x01D4 | O32: =CONCATENATE("0x",DEC2HEX(E32 + (64 * 8),4)) -> 0x0214 | P32: =CONCATENATE("0x",DEC2HEX(E32 + (64 * 9),4)) -> 0x0254 | Q32: =CONCATENATE("0x",DEC2HEX(E32 + (64 * 10),4)) -> 0x0294 | R32: =CONCATENATE("0x",DEC2HEX(E32 + (64 * 11),4)) -> 0x02D4 | S32: =CONCATENATE("0x",DEC2HEX(E32 + (64 * 12),4)) -> 0x0314 | T32: =CONCATENATE("0x",DEC2HEX(E32 + (64 * 13),4)) -> 0x0354 | U32: =CONCATENATE("0x",DEC2HEX(E32 + (64 * 14),4)) -> 0x0394
B33: Power Off Req [CIM -> Port bit 21] == true && Power Off Enable [Port -> CIM bit 21] == true 면 Servo Off | C33: POWER OFF REQ - CIM | E33: 21 | G33: =CONCATENATE("0x",DEC2HEX(E33,4)) -> 0x0015 | H33: =CONCATENATE("0x",DEC2HEX(E33 + (64 * 1),4)) -> 0x0055 | I33: =CONCATENATE("0x",DEC2HEX(E33 + (64 * 2),4)) -> 0x0095 | J33: =CONCATENATE("0x",DEC2HEX(E33 + (64 * 3),4)) -> 0x00D5 | K33: =CONCATENATE("0x",DEC2HEX(E33 + (64 * 4),4)) -> 0x0115 | L33: =CONCATENATE("0x",DEC2HEX(E33 + (64 * 5),4)) -> 0x0155 | M33: =CONCATENATE("0x",DEC2HEX(E33 + (64 * 6),4)) -> 0x0195 | N33: =CONCATENATE("0x",DEC2HEX(E33 + (64 * 7),4)) -> 0x01D5 | O33: =CONCATENATE("0x",DEC2HEX(E33 + (64 * 8),4)) -> 0x0215 | P33: =CONCATENATE("0x",DEC2HEX(E33 + (64 * 9),4)) -> 0x0255 | Q33: =CONCATENATE("0x",DEC2HEX(E33 + (64 * 10),4)) -> 0x0295 | R33: =CONCATENATE("0x",DEC2HEX(E33 + (64 * 11),4)) -> 0x02D5 | S33: =CONCATENATE("0x",DEC2HEX(E33 + (64 * 12),4)) -> 0x0315 | T33: =CONCATENATE("0x",DEC2HEX(E33 + (64 * 13),4)) -> 0x0355 | U33: =CONCATENATE("0x",DEC2HEX(E33 + (64 * 14),4)) -> 0x0395
C34: RESERVED | E34: 22 | G34: =CONCATENATE("0x",DEC2HEX(E34,4)) -> 0x0016 | H34: =CONCATENATE("0x",DEC2HEX(E34 + (64 * 1),4)) -> 0x0056 | I34: =CONCATENATE("0x",DEC2HEX(E34 + (64 * 2),4)) -> 0x0096 | J34: =CONCATENATE("0x",DEC2HEX(E34 + (64 * 3),4)) -> 0x00D6 | K34: =CONCATENATE("0x",DEC2HEX(E34 + (64 * 4),4)) -> 0x0116 | L34: =CONCATENATE("0x",DEC2HEX(E34 + (64 * 5),4)) -> 0x0156 | M34: =CONCATENATE("0x",DEC2HEX(E34 + (64 * 6),4)) -> 0x0196 | N34: =CONCATENATE("0x",DEC2HEX(E34 + (64 * 7),4)) -> 0x01D6 | O34: =CONCATENATE("0x",DEC2HEX(E34 + (64 * 8),4)) -> 0x0216 | P34: =CONCATENATE("0x",DEC2HEX(E34 + (64 * 9),4)) -> 0x0256 | Q34: =CONCATENATE("0x",DEC2HEX(E34 + (64 * 10),4)) -> 0x0296 | R34: =CONCATENATE("0x",DEC2HEX(E34 + (64 * 11),4)) -> 0x02D6 | S34: =CONCATENATE("0x",DEC2HEX(E34 + (64 * 12),4)) -> 0x0316 | T34: =CONCATENATE("0x",DEC2HEX(E34 + (64 * 13),4)) -> 0x0356 | U34: =CONCATENATE("0x",DEC2HEX(E34 + (64 * 14),4)) -> 0x0396
B35: (Port Busy X && Cycle Run X && Auto Control X) -> Port Direction Change (Input Status [Port -> CIM bit 10] true, Output Status [Port -> CIM bit 11] = false) | C35: In Mode Req - CIM | E35: 23 | G35: =CONCATENATE("0x",DEC2HEX(E35,4)) -> 0x0017 | H35: =CONCATENATE("0x",DEC2HEX(E35 + (64 * 1),4)) -> 0x0057 | I35: =CONCATENATE("0x",DEC2HEX(E35 + (64 * 2),4)) -> 0x0097 | J35: =CONCATENATE("0x",DEC2HEX(E35 + (64 * 3),4)) -> 0x00D7 | K35: =CONCATENATE("0x",DEC2HEX(E35 + (64 * 4),4)) -> 0x0117 | L35: =CONCATENATE("0x",DEC2HEX(E35 + (64 * 5),4)) -> 0x0157 | M35: =CONCATENATE("0x",DEC2HEX(E35 + (64 * 6),4)) -> 0x0197 | N35: =CONCATENATE("0x",DEC2HEX(E35 + (64 * 7),4)) -> 0x01D7 | O35: =CONCATENATE("0x",DEC2HEX(E35 + (64 * 8),4)) -> 0x0217 | P35: =CONCATENATE("0x",DEC2HEX(E35 + (64 * 9),4)) -> 0x0257 | Q35: =CONCATENATE("0x",DEC2HEX(E35 + (64 * 10),4)) -> 0x0297 | R35: =CONCATENATE("0x",DEC2HEX(E35 + (64 * 11),4)) -> 0x02D7 | S35: =CONCATENATE("0x",DEC2HEX(E35 + (64 * 12),4)) -> 0x0317 | T35: =CONCATENATE("0x",DEC2HEX(E35 + (64 * 13),4)) -> 0x0357 | U35: =CONCATENATE("0x",DEC2HEX(E35 + (64 * 14),4)) -> 0x0397
B36: (Port Busy X && Cycle Run X && Auto Control X) -> Port Direction Change (Output Status [Port -> CIM bit 11] true, Input Status [Port -> CIM bit 10] = false) | C36: Out Mode Req -CIM | E36: 24 | G36: =CONCATENATE("0x",DEC2HEX(E36,4)) -> 0x0018 | H36: =CONCATENATE("0x",DEC2HEX(E36 + (64 * 1),4)) -> 0x0058 | I36: =CONCATENATE("0x",DEC2HEX(E36 + (64 * 2),4)) -> 0x0098 | J36: =CONCATENATE("0x",DEC2HEX(E36 + (64 * 3),4)) -> 0x00D8 | K36: =CONCATENATE("0x",DEC2HEX(E36 + (64 * 4),4)) -> 0x0118 | L36: =CONCATENATE("0x",DEC2HEX(E36 + (64 * 5),4)) -> 0x0158 | M36: =CONCATENATE("0x",DEC2HEX(E36 + (64 * 6),4)) -> 0x0198 | N36: =CONCATENATE("0x",DEC2HEX(E36 + (64 * 7),4)) -> 0x01D8 | O36: =CONCATENATE("0x",DEC2HEX(E36 + (64 * 8),4)) -> 0x0218 | P36: =CONCATENATE("0x",DEC2HEX(E36 + (64 * 9),4)) -> 0x0258 | Q36: =CONCATENATE("0x",DEC2HEX(E36 + (64 * 10),4)) -> 0x0298 | R36: =CONCATENATE("0x",DEC2HEX(E36 + (64 * 11),4)) -> 0x02D8 | S36: =CONCATENATE("0x",DEC2HEX(E36 + (64 * 12),4)) -> 0x0318 | T36: =CONCATENATE("0x",DEC2HEX(E36 + (64 * 13),4)) -> 0x0358 | U36: =CONCATENATE("0x",DEC2HEX(E36 + (64 * 14),4)) -> 0x0398
C37: RESERVED | E37: 25 | G37: =CONCATENATE("0x",DEC2HEX(E37,4)) -> 0x0019 | H37: =CONCATENATE("0x",DEC2HEX(E37 + (64 * 1),4)) -> 0x0059 | I37: =CONCATENATE("0x",DEC2HEX(E37 + (64 * 2),4)) -> 0x0099 | J37: =CONCATENATE("0x",DEC2HEX(E37 + (64 * 3),4)) -> 0x00D9 | K37: =CONCATENATE("0x",DEC2HEX(E37 + (64 * 4),4)) -> 0x0119 | L37: =CONCATENATE("0x",DEC2HEX(E37 + (64 * 5),4)) -> 0x0159 | M37: =CONCATENATE("0x",DEC2HEX(E37 + (64 * 6),4)) -> 0x0199 | N37: =CONCATENATE("0x",DEC2HEX(E37 + (64 * 7),4)) -> 0x01D9 | O37: =CONCATENATE("0x",DEC2HEX(E37 + (64 * 8),4)) -> 0x0219 | P37: =CONCATENATE("0x",DEC2HEX(E37 + (64 * 9),4)) -> 0x0259 | Q37: =CONCATENATE("0x",DEC2HEX(E37 + (64 * 10),4)) -> 0x0299 | R37: =CONCATENATE("0x",DEC2HEX(E37 + (64 * 11),4)) -> 0x02D9 | S37: =CONCATENATE("0x",DEC2HEX(E37 + (64 * 12),4)) -> 0x0319 | T37: =CONCATENATE("0x",DEC2HEX(E37 + (64 * 13),4)) -> 0x0359 | U37: =CONCATENATE("0x",DEC2HEX(E37 + (64 * 14),4)) -> 0x0399
C38: AGV Type Req - CIM | E38: 26 | G38: =CONCATENATE("0x",DEC2HEX(E38,4)) -> 0x001A | H38: =CONCATENATE("0x",DEC2HEX(E38 + (64 * 1),4)) -> 0x005A | I38: =CONCATENATE("0x",DEC2HEX(E38 + (64 * 2),4)) -> 0x009A | J38: =CONCATENATE("0x",DEC2HEX(E38 + (64 * 3),4)) -> 0x00DA | K38: =CONCATENATE("0x",DEC2HEX(E38 + (64 * 4),4)) -> 0x011A | L38: =CONCATENATE("0x",DEC2HEX(E38 + (64 * 5),4)) -> 0x015A | M38: =CONCATENATE("0x",DEC2HEX(E38 + (64 * 6),4)) -> 0x019A | N38: =CONCATENATE("0x",DEC2HEX(E38 + (64 * 7),4)) -> 0x01DA | O38: =CONCATENATE("0x",DEC2HEX(E38 + (64 * 8),4)) -> 0x021A | P38: =CONCATENATE("0x",DEC2HEX(E38 + (64 * 9),4)) -> 0x025A | Q38: =CONCATENATE("0x",DEC2HEX(E38 + (64 * 10),4)) -> 0x029A | R38: =CONCATENATE("0x",DEC2HEX(E38 + (64 * 11),4)) -> 0x02DA | S38: =CONCATENATE("0x",DEC2HEX(E38 + (64 * 12),4)) -> 0x031A | T38: =CONCATENATE("0x",DEC2HEX(E38 + (64 * 13),4)) -> 0x035A | U38: =CONCATENATE("0x",DEC2HEX(E38 + (64 * 14),4)) -> 0x039A
C39: MGV Type Req - CIM | E39: 27 | G39: =CONCATENATE("0x",DEC2HEX(E39,4)) -> 0x001B | H39: =CONCATENATE("0x",DEC2HEX(E39 + (64 * 1),4)) -> 0x005B | I39: =CONCATENATE("0x",DEC2HEX(E39 + (64 * 2),4)) -> 0x009B | J39: =CONCATENATE("0x",DEC2HEX(E39 + (64 * 3),4)) -> 0x00DB | K39: =CONCATENATE("0x",DEC2HEX(E39 + (64 * 4),4)) -> 0x011B | L39: =CONCATENATE("0x",DEC2HEX(E39 + (64 * 5),4)) -> 0x015B | M39: =CONCATENATE("0x",DEC2HEX(E39 + (64 * 6),4)) -> 0x019B | N39: =CONCATENATE("0x",DEC2HEX(E39 + (64 * 7),4)) -> 0x01DB | O39: =CONCATENATE("0x",DEC2HEX(E39 + (64 * 8),4)) -> 0x021B | P39: =CONCATENATE("0x",DEC2HEX(E39 + (64 * 9),4)) -> 0x025B | Q39: =CONCATENATE("0x",DEC2HEX(E39 + (64 * 10),4)) -> 0x029B | R39: =CONCATENATE("0x",DEC2HEX(E39 + (64 * 11),4)) -> 0x02DB | S39: =CONCATENATE("0x",DEC2HEX(E39 + (64 * 12),4)) -> 0x031B | T39: =CONCATENATE("0x",DEC2HEX(E39 + (64 * 13),4)) -> 0x035B | U39: =CONCATENATE("0x",DEC2HEX(E39 + (64 * 14),4)) -> 0x039B
C40: RESERVEDOHTOHT | E40: 28 | G40: =CONCATENATE("0x",DEC2HEX(E40,4)) -> 0x001C | H40: =CONCATENATE("0x",DEC2HEX(E40 + (64 * 1),4)) -> 0x005C | I40: =CONCATENATE("0x",DEC2HEX(E40 + (64 * 2),4)) -> 0x009C | J40: =CONCATENATE("0x",DEC2HEX(E40 + (64 * 3),4)) -> 0x00DC | K40: =CONCATENATE("0x",DEC2HEX(E40 + (64 * 4),4)) -> 0x011C | L40: =CONCATENATE("0x",DEC2HEX(E40 + (64 * 5),4)) -> 0x015C | M40: =CONCATENATE("0x",DEC2HEX(E40 + (64 * 6),4)) -> 0x019C | N40: =CONCATENATE("0x",DEC2HEX(E40 + (64 * 7),4)) -> 0x01DC | O40: =CONCATENATE("0x",DEC2HEX(E40 + (64 * 8),4)) -> 0x021C | P40: =CONCATENATE("0x",DEC2HEX(E40 + (64 * 9),4)) -> 0x025C | Q40: =CONCATENATE("0x",DEC2HEX(E40 + (64 * 10),4)) -> 0x029C | R40: =CONCATENATE("0x",DEC2HEX(E40 + (64 * 11),4)) -> 0x02DC | S40: =CONCATENATE("0x",DEC2HEX(E40 + (64 * 12),4)) -> 0x031C | T40: =CONCATENATE("0x",DEC2HEX(E40 + (64 * 13),4)) -> 0x035C | U40: =CONCATENATE("0x",DEC2HEX(E40 + (64 * 14),4)) -> 0x039C
...

Sheet Port Word
M1: Offset | N1: =HEX2DEC(80) -> 128
G2: SSONE -> CV | K2: PORT | L2: 30101 | M2: 30102 | N2: 30103 | O2: 30104 | P2: 30201 | Q2: 30202 | R2: 30203 | S2: 30204 | T2: 30301 | U2: 30302 | V2: 30303 | W2: 30304
K3: DP-Fosb | L3: MGV IN (AGV기능포함) | M3: MGV OUT (AGV기능포함) | N3: AGV IN | O3: AGV OUT | P3: OHT IN (MGV기능포함) | Q3: OHT OUT (MGV기능포함) | R3: OHT IN (MGV기능포함) | S3: OHT OUT (MGV기능포함) | T3: AUTO IN | U3: AUTO IN | V3: AUTO OUT | W3: AUTO OUT
K4: DP-Wafer | L4: MGV IN (AGV기능미사용) | M4: MGV OUT (AGV기능미사용) | N4: AGV IN (MGV기능미사용) | O4: AGV OUT (MGV기능미사용) | P4: OHT IN (MGV기능포함) | Q4: OHT OUT (MGV기능포함) | R4: OHT IN (MGV기능포함) | S4: OHT OUT (MGV기능포함) | T4: AUTO IN | U4: AUTO IN | V4: AUTO OUT | W4: AUTO OUT
K5: RECON-CST | L5: MGV IN (AGV기능포함) | M5: MGV OUT (AGV기능포함) | N5: AGV IN | O5: AGV OUT | P5: OHT IN (MGV기능포함) | Q5: OHT OUT (MGV기능포함) | R5: OHT IN (MGV기능포함) | S5: OHT OUT (MGV기능포함) | T5: AUTO IN | U5: AUTO IN | V5: AUTO OUT | W5: AUTO OUT
K6: RECON-OVEN | L6: MGV IN (AGV기능포함) | M6: MGV OUT (AGV기능포함) | N6: AGV IN | O6: AGV OUT | P6: OHT IN (MGV기능포함) | Q6: OHT OUT (MGV기능포함) | R6: OHT IN (MGV기능포함) | S6: OHT OUT (MGV기능포함) | T6: AUTO IN | U6: AUTO IN | V6: AUTO OUT | W6: AUTO OUT
K7: RDL-FOUP | L7: MGV IN (AGV기능포함) | M7: MGV OUT (AGV기능포함) | N7: AGV IN | O7: AGV OUT | P7: OHT IN (MGV기능포함) | Q7: OHT OUT (MGV기능포함) | R7: OHT IN (MGV기능포함) | S7: OHT OUT (MGV기능포함) | T7: AUTO IN | U7: AUTO IN | V7: AUTO OUT | W7: AUTO OUT
K8: RDL-OVEN | L8: MGV IN (AGV기능포함) | M8: MGV OUT (AGV기능포함) | N8: AGV IN | O8: AGV OUT | P8: OHT IN (MGV기능포함) | Q8: OHT OUT (MGV기능포함) | R8: OHT IN (MGV기능포함) | S8: OHT OUT (MGV기능포함) | T8: AUTO IN | U8: AUTO IN | V8: AUTO OUT | W8: AUTO OUT
K9: EOL-CST | L9: MGV IN (AGV기능포함) | M9: MGV OUT (AGV기능포함) | N9: AGV IN | O9: AGV OUT | P9: OHT IN (MGV기능포함) | Q9: OHT OUT (MGV기능포함) | R9: OHT IN (MGV기능포함) | S9: OHT OUT (MGV기능포함) | T9: AUTO IN | U9: AUTO IN | V9: AUTO OUT | W9: AUTO OUT
K10: DIE BANK | L10: MGV IN (AGV기능포함) | M10: MGV OUT (AGV기능포함) | N10: AGV IN | O10: AGV OUT | P10: OHT IN (MGV기능포함) | Q10: OHT OUT (MGV기능포함) | R10: OHT IN (MGV기능포함) | S10: OHT OUT (MGV기능포함) | T10: AUTO IN | U10: AUTO IN | V10: AUTO OUT | W10: AUTO OUT
B11: Buffer Sensor Detail | D11: Commet | G11: Master Program Comment | H11: Comment | I11: Description | J11: DEC | K11: Word Group | L11: STK->PORT | M11: STK->PORT | N11: STK->PORT | O11: STK->PORT | P11: STK->PORT | Q11: STK->PORT | R11: STK->PORT | S11: STK->PORT | T11: STK->PORT | U11: STK->PORT | V11: STK->PORT | W11: STK->PORT
B12: C/V High Speed FWD Move | C12: Bit | H12: Buffer#1 Control - MST | J12: 0 | K12: 1 | L12: =CONCATENATE("0x",DEC2HEX(J12,4)) -> 0x0000 | M12: =CONCATENATE("0x",DEC2HEX(J12 + (128 * 1),4)) -> 0x0080 | N12: =CONCATENATE("0x",DEC2HEX(J12 + (128 * 2),4)) -> 0x0100 | O12: =CONCATENATE("0x",DEC2HEX(J12 + (128 * 3),4)) -> 0x0180 | P12: =CONCATENATE("0x",DEC2HEX(J12 + (128 * 4),4)) -> 0x0200 | Q12: =CONCATENATE("0x",DEC2HEX(J12 + (128 * 5),4)) -> 0x0280 | R12: =CONCATENATE("0x",DEC2HEX(J12 + (128 * 6),4)) -> 0x0300 | S12: =CONCATENATE("0x",DEC2HEX(J12 + (128 * 7),4)) -> 0x0380 | T12: =CONCATENATE("0x",DEC2HEX(J12 + (128 * 8),4)) -> 0x0400 | U12: =CONCATENATE("0x",DEC2HEX(J12 + (128 * 9),4)) -> 0x0480 | V12: =CONCATENATE("0x",DEC2HEX(J12 + (128 * 10),4)) -> 0x0500 | W12: =CONCATENATE("0x",DEC2HEX(J12 + (128 * 11),4)) -> 0x0580
B13: C/V Low Speed FWD Move | C13: Bit | H13: Buffer#1 Control | J13: 1 | L13: =CONCATENATE("0x",DEC2HEX(J13,4)) -> 0x0001 | M13: =CONCATENATE("0x",DEC2HEX(J13 + (128 * 1),4)) -> 0x0081 | N13: =CONCATENATE("0x",DEC2HEX(J13 + (128 * 2),4)) -> 0x0101 | O13: =CONCATENATE("0x",DEC2HEX(J13 + (128 * 3),4)) -> 0x0181 | P13: =CONCATENATE("0x",DEC2HEX(J13 + (128 * 4),4)) -> 0x0201 | Q13: =CONCATENATE("0x",DEC2HEX(J13 + (128 * 5),4)) -> 0x0281 | R13: =CONCATENATE("0x",DEC2HEX(J13 + (128 * 6),4)) -> 0x0301 | S13: =CONCATENATE("0x",DEC2HEX(J13 + (128 * 7),4)) -> 0x0381 | T13: =CONCATENATE("0x",DEC2HEX(J13 + (128 * 8),4)) -> 0x0401 | U13: =CONCATENATE("0x",DEC2HEX(J13 + (128 * 9),4)) -> 0x0481 | V13: =CONCATENATE("0x",DEC2HEX(J13 + (128 * 10),4)) -> 0x0501 | W13: =CONCATENATE("0x",DEC2HEX(J13 + (128 * 11),4)) -> 0x0581
